Workbook

Sheet Species Summary
A1: Open-Source Recordings — Species Summary
A2: Public focal recordings from Xeno-canto set 2146 "Costa Rica Birds" (curated by Bobby Wilcox), recorded July 2016 around Arenal (600–750 m) and Monteverde (1400–1500 m). 77 recordings, 52 species, all CC BY-NC-SA 4.0. Not site data: species are grouped by whether eBird records them at La Selva Biological Station (species/la_selva_ebird.csv, EBD relJul-2026, 33,576 checklists). Names follow eBird/Clements as in that list; the Xeno-canto name is kept on the All Recordings sheet. Downloads and 32 kHz FLAC conversions are on the LaCie under data-prep/xc and data-prep/xc_flac.
A3: =HYPERLINK("https://xeno-canto.org/set/2146","Xeno-canto set 2146 (source)") -> Xeno-canto set 2146 (source)
A4: =HYPERLINK("https://github.com/kaanturan3/data-prep","data-prep repo (manifests, species lists, scripts)") -> data-prep repo (manifests, species lists, scripts)
A5: Species | B5: Scientific name | C5: # Recordings | D5: Data notes | E5: Recording 1 | F5: Recording 2 | G5: Recording 3
A6: BIRDS ON THE LA SELVA LIST — 44 species (61 recordings; usable as positive training examples for the site)
A7: Bananaquit | B7: Coereba flaveola | C7: =COUNTIF('All Recordings'!$F$2:$F$78,A7) -> 3 | D7: Quality B×3; song; Arenal Observatory Lodge; La Selva: on 29.5% of checklists | E7: =HYPERLINK("https://xeno-canto.org/331385","XC331385 (B, song)") -> XC331385 (B, song) | F7: =HYPERLINK("https://xeno-canto.org/331386","XC331386 (B, song)") -> XC331386 (B, song) | G7: =HYPERLINK("https://xeno-canto.org/331387","XC331387 (B, song)") -> XC331387 (B, song)
A8: Melodious Blackbird | B8: Dives dives | C8: =COUNTIF('All Recordings'!$F$2:$F$78,A8) -> 3 | D8: Quality B×2, C×1; call; song; Arenal Observatory Lodge; La Selva: on 4.8% of checklists | E8: =HYPERLINK("https://xeno-canto.org/331320","XC331320 (C, song)") -> XC331320 (C, song) | F8: =HYPERLINK("https://xeno-canto.org/331322","XC331322 (B, song)") -> XC331322 (B, song) | G8: =HYPERLINK("https://xeno-canto.org/331323","XC331323 (B, call)") -> XC331323 (B, call)
A9: Southern House Wren | B9: Troglodytes musculus | C9: =COUNTIF('All Recordings'!$F$2:$F$78,A9) -> 3 | D9: Quality B×2, C×1; song; Arenal Observatory Lodge / Hotel El Bosque; La Selva: on 15.3% of checklists; Xeno-canto files it as House Wren (Troglodytes aedon); eBird splits the Costa Rican birds as Southern House Wren | E9: =HYPERLINK("https://xeno-canto.org/331326","XC331326 (B, song)") -> XC331326 (B, song) | F9: =HYPERLINK("https://xeno-canto.org/331333","XC331333 (C, song)") -> XC331333 (C, song) | G9: =HYPERLINK("https://xeno-canto.org/332269","XC332269 (B, song)") -> XC332269 (B, song)
A10: Three-wattled Bellbird | B10: Procnias tricarunculatus | C10: =COUNTIF('All Recordings'!$F$2:$F$78,A10) -> 3 | D10: Quality A×3; song; Children's Eternal Rain Forest Bajo del Tigre / Reserva Curi-Cancha; La Selva: on 0.5% of checklists | E10: =HYPERLINK("https://xeno-canto.org/331252","XC331252 (A, song)") -> XC331252 (A, song) | F10: =HYPERLINK("https://xeno-canto.org/332147","XC332147 (A, song)") -> XC332147 (A, song) | G10: =HYPERLINK("https://xeno-canto.org/332261","XC332261 (A, song)") -> XC332261 (A, song)
A11: Black-headed Nightingale-Thrush | B11: Catharus mexicanus | C11: =COUNTIF('All Recordings'!$F$2:$F$78,A11) -> 2 | D11: Quality A×1, B×1; song; Reserva Curi-Cancha; La Selva: on 0.1% of checklists | E11: =HYPERLINK("https://xeno-canto.org/332446","XC332446 (A, song)") -> XC332446 (A, song) | F11: =HYPERLINK("https://xeno-canto.org/332447","XC332447 (B, song)") -> XC332447 (B, song)
A12: Black-striped Sparrow | B12: Arremonops conirostris | C12: =COUNTIF('All Recordings'!$F$2:$F$78,A12) -> 2 | D12: Quality B×1, C×1; call; song; Arenal Observatory Lodge; La Selva: on 4.3% of checklists | E12: =HYPERLINK("https://xeno-canto.org/331434","XC331434 (B, song)") -> XC331434 (B, song) | F12: =HYPERLINK("https://xeno-canto.org/331470","XC331470 (C, call)") -> XC331470 (C, call)
A13: Black-throated Wren | B13: Pheugopedius atrogularis | C13: =COUNTIF('All Recordings'!$F$2:$F$78,A13) -> 2 | D13: Quality B×2; song; Arenal Observatory Lodge; La Selva: on 12.0% of checklists | E13: =HYPERLINK("https://xeno-canto.org/331388","XC331388 (B, song)") -> XC331388 (B, song) | F13: =HYPERLINK("https://xeno-canto.org/331389","XC331389 (B, song)") -> XC331389 (B, song)
A14: Brown Jay | B14: Cyanocorax morio | C14: =COUNTIF('All Recordings'!$F$2:$F$78,A14) -> 2 | D14: Quality B×2; alarm call; call; Arenal Observatory Lodge / Reserva Curi-Cancha; La Selva: on 0.9% of checklists; Xeno-canto uses the older genus Psilorhinus | E14: =HYPERLINK("https://xeno-canto.org/331311","XC331311 (B, alarm call)") -> XC331311 (B, alarm call) | F14: =HYPERLINK("https://xeno-canto.org/332502","XC332502 (B, call)") -> XC332502 (B, call)
A15: Keel-billed Toucan | B15: Ramphastos sulfuratus | C15: =COUNTIF('All Recordings'!$F$2:$F$78,A15) -> 2 | D15: Quality B×2; call; Reserva Curi-Cancha; La Selva: on 39.0% of checklists | E15: =HYPERLINK("https://xeno-canto.org/332512","XC332512 (B, call)") -> XC332512 (B, call) | F15: =HYPERLINK("https://xeno-canto.org/332528","XC332528 (B, call)") -> XC332528 (B, call)
A16: Montezuma Oropendola | B16: Psarocolius montezuma | C16: =COUNTIF('All Recordings'!$F$2:$F$78,A16) -> 2 | D16: Quality C×2; song; Arenal Observatory Lodge / Hotel Castillo del Arenal; La Selva: on 49.2% of checklists | E16: =HYPERLINK("https://xeno-canto.org/331372","XC331372 (C, song)") -> XC331372 (C, song) | F16: =HYPERLINK("https://xeno-canto.org/331640","XC331640 (C, song)") -> XC331640 (C, song)
A17: Nightingale Wren | B17: Microcerculus philomela | C17: =COUNTIF('All Recordings'!$F$2:$F$78,A17) -> 2 | D17: Quality B×1, C×1; song; Arenal Observatory Lodge; La Selva: on 0.3% of checklists | E17: =HYPERLINK("https://xeno-canto.org/331336","XC331336 (C, song)") -> XC331336 (C, song) | F17: =HYPERLINK("https://xeno-canto.org/331356","XC331356 (B, song)") -> XC331356 (B, song)
A18: Scaly-breasted Hummingbird | B18: Phaeochroa cuvierii | C18: =COUNTIF('All Recordings'!$F$2:$F$78,A18) -> 2 | D18: Quality A×1, C×1; song; Arenal Observatory Lodge; La Selva: on 4.9% of checklists | E18: =HYPERLINK("https://xeno-canto.org/331334","XC331334 (C, song)") -> XC331334 (C, song) | F18: =HYPERLINK("https://xeno-canto.org/331436","XC331436 (A, song)") -> XC331436 (A, song)
A19: Stripe-breasted Wren | B19: Cantorchilus thoracicus | C19: =COUNTIF('All Recordings'!$F$2:$F$78,A19) -> 2 | D19: Quality A×1, B×1; call; song; Arenal Observatory Lodge; La Selva: on 20.4% of checklists; Seed species (in the June 2022 extracts); XC331314 has people talking in the background | E19: =HYPERLINK("https://xeno-canto.org/331314","XC331314 (B, call)") -> XC331314 (B, call) | F19: =HYPERLINK("https://xeno-canto.org/331465","XC331465 (A, song)") -> XC331465 (A, song)
A20: Blue-black Grosbeak | B20: Cyanoloxia cyanoides | C20: =COUNTIF('All Recordings'!$F$2:$F$78,A20) -> 1 | D20: Quality C×1; song; Hotel Castillo del Arenal; La Selva: on 10.5% of checklists | E20: =HYPERLINK("https://xeno-canto.org/331643","XC331643 (C, song)") -> XC331643 (C, song)
A21: Blue-gray Tanager | B21: Thraupis episcopus | C21: =COUNTIF('All Recordings'!$F$2:$F$78,A21) -> 1 | D21: Quality C×1; song; Monteverde; La Selva: on 38.7% of checklists | E21: =HYPERLINK("https://xeno-canto.org/332386","XC332386 (C, song)") -> XC332386 (C, song)
A22: Boat-billed Flycatcher | B22: Megarynchus pitangua | C22: =COUNTIF('All Recordings'!$F$2:$F$78,A22) -> 1 | D22: Quality B×1; call; Hotel El Bosque; La Selva: on 26.0% of checklists | E22: =HYPERLINK("https://xeno-canto.org/332270","XC332270 (B, call)") -> XC332270 (B, call)
A23: Buff-rumped Warbler | B23: Myiothlypis fulvicauda | C23: =COUNTIF('All Recordings'!$F$2:$F$78,A23) -> 1 | D23: Quality C×1; song; Arenal Observatory Lodge; La Selva: on 19.3% of checklists | E23: =HYPERLINK("https://xeno-canto.org/331463","XC331463 (C, song)") -> XC331463 (C, song)
A24: Buff-throated Saltator | B24: Saltator maximus | C24: =COUNTIF('All Recordings'!$F$2:$F$78,A24) -> 1 | D24: Quality B×1; song; Hotel Castillo del Arenal; La Selva: on 32.5% of checklists | E24: =HYPERLINK("https://xeno-canto.org/331642","XC331642 (B, song)") -> XC331642 (B, song)
A25: Cinnamon Becard | B25: Pachyramphus cinnamomeus | C25: =COUNTIF('All Recordings'!$F$2:$F$78,A25) -> 1 | D25: Quality B×1; song; Arenal Observatory Lodge; La Selva: on 26.4% of checklists | E25: =HYPERLINK("https://xeno-canto.org/331390","XC331390 (B, song)") -> XC331390 (B, song)
A26: Clay-colored Thrush | B26: Turdus grayi | C26: =COUNTIF('All Recordings'!$F$2:$F$78,A26) -> 1 | D26: Quality B×1; song; Arenal Observatory Lodge; La Selva: on 44.6% of checklists | E26: =HYPERLINK("https://xeno-canto.org/331431","XC331431 (B, song)") -> XC331431 (B, song)
A27: Collared Trogon | B27: Trogon collaris | C27: =COUNTIF('All Recordings'!$F$2:$F$78,A27) -> 1 | D27: Quality C×1; call; Reserva Curi-Cancha; La Selva: on 0.1% of checklists | E27: =HYPERLINK("https://xeno-canto.org/332450","XC332450 (C, call)") -> XC332450 (C, call)
A28: Common Tody-Flycatcher | B28: Todirostrum cinereum | C28: =COUNTIF('All Recordings'!$F$2:$F$78,A28) -> 1 | D28: Quality B×1; call; Arenal Observatory Lodge; La Selva: on 26.2% of checklists | E28: =HYPERLINK("https://xeno-canto.org/331449","XC331449 (B, call)") -> XC331449 (B, call)
A29: Crested Guan | B29: Penelope purpurascens | C29: =COUNTIF('All Recordings'!$F$2:$F$78,A29) -> 1 | D29: Quality A×1; call; Arenal Observatory Lodge; La Selva: on 38.5% of checklists | E29: =HYPERLINK("https://xeno-canto.org/331367","XC331367 (A, call)") -> XC331367 (A, call)
A30: Gray-capped Flycatcher | B30: Myiozetetes granadensis | C30: =COUNTIF('All Recordings'!$F$2:$F$78,A30) -> 1 | D30: Quality B×1; call; Arenal Observatory Lodge; La Selva: on 32.1% of checklists | E30: =HYPERLINK("https://xeno-canto.org/331460","XC331460 (B, call)") -> XC331460 (B, call)
A31: Gray-crowned Yellowthroat | B31: Geothlypis poliocephala | C31: =COUNTIF('All Recordings'!$F$2:$F$78,A31) -> 1 | D31: Quality B×1; song; Reserva Curi-Cancha; La Selva: on 0.4% of checklists | E31: =HYPERLINK("https://xeno-canto.org/332260","XC332260 (B, song)") -> XC332260 (B, song)
A32: Gray-headed Chachalaca | B32: Ortalis cinereiceps | C32: =COUNTIF('All Recordings'!$F$2:$F$78,A32) -> 1 | D32: Quality C×1; alarm call; Hotel El Bosque; La Selva: on 5.9% of checklists | E32: =HYPERLINK("https://xeno-canto.org/331639","XC331639 (C, alarm call)") -> XC331639 (C, alarm call)
A33: Lesser Greenlet | B33: Pachysylvia decurtata | C33: =COUNTIF('All Recordings'!$F$2:$F$78,A33) -> 1 | D33: Quality B×1; call; song; Reserva Curi-Cancha; La Selva: on 22.8% of checklists; Seed species (in the June 2022 extracts) | E33: =HYPERLINK("https://xeno-canto.org/332387","XC332387 (B, call)") -> XC332387 (B, call)
A34: Orange-chinned Parakeet | B34: Brotogeris jugularis | C34: =COUNTIF('All Recordings'!$F$2:$F$78,A34) -> 1 | D34: Quality B×1; call; Arenal Observatory Lodge; La Selva: on 23.5% of checklists | E34: =HYPERLINK("https://xeno-canto.org/331362","XC331362 (B, call)") -> XC331362 (B, call)
A35: Red-lored Amazon | B35: Amazona autumnalis | C35: =COUNTIF('All Recordings'!$F$2:$F$78,A35) -> 1 | D35: Quality B×1; call; Hotel Castillo del Arenal; La Selva: on 32.9% of checklists; Seed species (in the June 2022 extracts) | E35: =HYPERLINK("https://xeno-canto.org/331641","XC331641 (B, call)") -> XC331641 (B, call)
A36: Resplendent Quetzal | B36: Pharomachrus mocinno | C36: =COUNTIF('All Recordings'!$F$2:$F$78,A36) -> 1 | D36: Quality B×1; alarm call; Reserva Curi-Cancha; La Selva: on 0.0% of checklists | E36: =HYPERLINK("https://xeno-canto.org/332262","XC332262 (B, alarm call)") -> XC332262 (B, alarm call)
A37: Rufous-tailed Hummingbird | B37: Amazilia tzacatl | C37: =COUNTIF('All Recordings'!$F$2:$F$78,A37) -> 1 | D37: Quality C×1; song; Hotel El Bosque; La Selva: on 45.9% of checklists | E37: =HYPERLINK("https://xeno-canto.org/332268","XC332268 (C, song)") -> XC332268 (C, song)
A38: Scarlet-rumped Tanager | B38: Ramphocelus passerinii | C38: =COUNTIF('All Recordings'!$F$2:$F$78,A38) -> 1 | D38: Quality B×1; song; Arenal Observatory Lodge; La Selva: on 54.5% of checklists | E38: =HYPERLINK("https://xeno-canto.org/331462","XC331462 (B, song)") -> XC331462 (B, song)
A39: Slaty Spinetail | B39: Synallaxis brachyura | C39: =COUNTIF('All Recordings'!$F$2:$F$78,A39) -> 1 | D39: Quality B×1; call; Arenal Observatory Lodge; La Selva: on 1.2% of checklists | E39: =HYPERLINK("https://xeno-canto.org/331381","XC331381 (B, call)") -> XC331381 (B, call)
A40: Spotted Antbird | B40: Hylophylax naevioides | C40: =COUNTIF('All Recordings'!$F$2:$F$78,A40) -> 1 | D40: Quality C×1; alarm call; call; Arenal Observatory Lodge; La Selva: on 5.1% of checklists | E40: =HYPERLINK("https://xeno-canto.org/331600","XC331600 (C, alarm call)") -> XC331600 (C, alarm call)
...

Sheet All Recordings
A1: File | B1: Folder | C1: Date | D1: Local time | E1: Label (as written on Xeno-canto) | F1: Species (canonical) | G1: Notes | H1: Quality | I1: Status | J1: Xeno-canto Link
A2: XC331252.mp3 | B2: xc_flac | C2: 2016-07-29 | D2: 11:30 | E2: Three-wattled Bellbird (Procnias tricarunculatus) | F2: Three-wattled Bellbird | G2: song; Reserva Curi-Cancha, Monteverde, 1500 m | H2: A | I2: La Selva species | J2: =HYPERLINK("https://xeno-canto.org/331252","Open on Xeno-canto") -> Open on Xeno-canto
A3: XC331311.mp3 | B3: xc_flac | C3: 2016-07-24 | D3: 14:00 | E3: Brown Jay (Psilorhinus morio) | F3: Brown Jay | G3: alarm call, call; Arenal Observatory Lodge, Fortuna, Costa Rica, 750 m; Xeno-canto uses the older genus Psilorhinus | H3: B | I3: La Selva species | J3: =HYPERLINK("https://xeno-canto.org/331311","Open on Xeno-canto") -> Open on Xeno-canto
A4: XC331314.mp3 | B4: xc_flac | C4: 2016-07-24 | D4: 15:30 | E4: Stripe-breasted Wren (Cantorchilus thoracicus) | F4: Stripe-breasted Wren | G4: call; people talking in background; Arenal Observatory Lodge, Fortuna, Costa Rica, 750 m | H4: B | I4: La Selva species | J4: =HYPERLINK("https://xeno-canto.org/331314","Open on Xeno-canto") -> Open on Xeno-canto
A5: XC331320.mp3 | B5: xc_flac | C5: 2016-07-24 | D5: 16:30 | E5: Melodious Blackbird (Dives dives) | F5: Melodious Blackbird | G5: song; Arenal Observatory Lodge, Fortuna, Costa Rica, 750 m | H5: C | I5: La Selva species | J5: =HYPERLINK("https://xeno-canto.org/331320","Open on Xeno-canto") -> Open on Xeno-canto
A6: XC331322.mp3 | B6: xc_flac | C6: 2016-07-25 | D6: 09:00 | E6: Melodious Blackbird (Dives dives) | F6: Melodious Blackbird | G6: song; Arenal Observatory Lodge, Fortuna, Costa Rica, 750 m | H6: B | I6: La Selva species | J6: =HYPERLINK("https://xeno-canto.org/331322","Open on Xeno-canto") -> Open on Xeno-canto
A7: XC331323.mp3 | B7: xc_flac | C7: 2016-07-26 | D7: 18:00 | E7: Melodious Blackbird (Dives dives) | F7: Melodious Blackbird | G7: call; Arenal Observatory Lodge, Fortuna, Costa Rica, 750 m | H7: B | I7: La Selva species | J7: =HYPERLINK("https://xeno-canto.org/331323","Open on Xeno-canto") -> Open on Xeno-canto
A8: XC331326.mp3 | B8: xc_flac | C8: 2016-07-24 | D8: 16:30 | E8: House Wren (Troglodytes aedon) | F8: Southern House Wren | G8: song; Arenal Observatory Lodge, Fortuna, Costa Rica, 750 m; Xeno-canto files it as House Wren (Troglodytes aedon); eBird splits the Costa Rican birds as Southern House Wren | H8: B | I8: La Selva species | J8: =HYPERLINK("https://xeno-canto.org/331326","Open on Xeno-canto") -> Open on Xeno-canto
A9: XC331328.mp3 | B9: xc_flac | C9: 2016-07-24 | D9: 17:00 | E9: Sulphur-bellied Flycatcher (Myiodynastes luteiventris) | F9: Sulphur-bellied Flycatcher | G9: call; Arenal Observatory Lodge, Fortuna, Costa Rica, 750 m | H9: B | I9: La Selva species | J9: =HYPERLINK("https://xeno-canto.org/331328","Open on Xeno-canto") -> Open on Xeno-canto
A10: XC331333.mp3 | B10: xc_flac | C10: 2016-07-24 | D10: 17:30 | E10: House Wren (Troglodytes aedon) | F10: Southern House Wren | G10: song; Arenal Observatory Lodge, Fortuna, Costa Rica, 750 m; Xeno-canto files it as House Wren (Troglodytes aedon); eBird splits the Costa Rican birds as Southern House Wren | H10: C | I10: La Selva species | J10: =HYPERLINK("https://xeno-canto.org/331333","Open on Xeno-canto") -> Open on Xeno-canto
A11: XC331334.mp3 | B11: xc_flac | C11: 2016-07-24 | D11: 17:30 | E11: Scaly-breasted Hummingbird (Phaeochroa cuvierii) | F11: Scaly-breasted Hummingbird | G11: song; Arenal Observatory Lodge, Fortuna, Costa Rica, 750 m | H11: C | I11: La Selva species | J11: =HYPERLINK("https://xeno-canto.org/331334","Open on Xeno-canto") -> Open on Xeno-canto
A12: XC331335.mp3 | B12: xc_flac | C12: 2016-07-25 | D12: 09:00 | E12: Yellow-throated Toucan (Ramphastos ambiguus) | F12: Yellow-throated Toucan | G12: call; Arenal Observatory Lodge, Fortuna, Costa Rica, 750 m | H12: C | I12: La Selva species | J12: =HYPERLINK("https://xeno-canto.org/331335","Open on Xeno-canto") -> Open on Xeno-canto
A13: XC331336.mp3 | B13: xc_flac | C13: 2016-07-25 | D13: 09:00 | E13: Northern Nightingale-Wren (Microcerculus philomela) | F13: Nightingale Wren | G13: song; Arenal Observatory Lodge, Fortuna, Costa Rica, 750 m | H13: C | I13: La Selva species | J13: =HYPERLINK("https://xeno-canto.org/331336","Open on Xeno-canto") -> Open on Xeno-canto
A14: XC331354.mp3 | B14: xc_flac | C14: 2016-07-25 | D14: 12:00 | E14: Variable Seedeater (Sporophila corvina) | F14: Variable Seedeater | G14: song; Arenal Observatory Lodge, Fortuna, Costa Rica, 750 m | H14: C | I14: La Selva species | J14: =HYPERLINK("https://xeno-canto.org/331354","Open on Xeno-canto") -> Open on Xeno-canto
A15: XC331355.mp3 | B15: xc_flac | C15: 2016-07-25 | D15: 12:30 | E15: Thicket Antpitta (Hylopezus dives) | F15: Thicket Antpitta | G15: song; Arenal Observatory Lodge, Fortuna, Costa Rica, 750 m; Xeno-canto uses the older genus Hylopezus | H15: C | I15: La Selva species | J15: =HYPERLINK("https://xeno-canto.org/331355","Open on Xeno-canto") -> Open on Xeno-canto
A16: XC331356.mp3 | B16: xc_flac | C16: 2016-07-25 | D16: 12:30 | E16: Northern Nightingale-Wren (Microcerculus philomela) | F16: Nightingale Wren | G16: song; Arenal Observatory Lodge, Fortuna, Costa Rica, 750 m | H16: B | I16: La Selva species | J16: =HYPERLINK("https://xeno-canto.org/331356","Open on Xeno-canto") -> Open on Xeno-canto
A17: XC331362.mp3 | B17: xc_flac | C17: 2016-07-25 | D17: 16:30 | E17: Orange-chinned Parakeet (Brotogeris jugularis) | F17: Orange-chinned Parakeet | G17: call; Arenal Observatory Lodge, Fortuna, Costa Rica, 750 m | H17: B | I17: La Selva species | J17: =HYPERLINK("https://xeno-canto.org/331362","Open on Xeno-canto") -> Open on Xeno-canto
A18: XC331367.mp3 | B18: xc_flac | C18: 2016-07-26 | D18: 06:00 | E18: Crested Guan (Penelope purpurascens) | F18: Crested Guan | G18: call; Arenal Observatory Lodge, Fortuna, Costa Rica, 750 m | H18: A | I18: La Selva species | J18: =HYPERLINK("https://xeno-canto.org/331367","Open on Xeno-canto") -> Open on Xeno-canto
A19: XC331372.mp3 | B19: xc_flac | C19: 2016-07-26 | D19: 06:00 | E19: Montezuma Oropendola (Psarocolius montezuma) | F19: Montezuma Oropendola | G19: song; Arenal Observatory Lodge, Fortuna, Costa Rica, 750 m | H19: C | I19: La Selva species | J19: =HYPERLINK("https://xeno-canto.org/331372","Open on Xeno-canto") -> Open on Xeno-canto
A20: XC331381.mp3 | B20: xc_flac | C20: 2016-07-26 | D20: 07:00 | E20: Slaty Spinetail (Synallaxis brachyura) | F20: Slaty Spinetail | G20: call; Arenal Observatory Lodge, Fortuna, Costa Rica, 750 m | H20: B | I20: La Selva species | J20: =HYPERLINK("https://xeno-canto.org/331381","Open on Xeno-canto") -> Open on Xeno-canto
A21: XC331385.mp3 | B21: xc_flac | C21: 2016-07-26 | D21: 06:00 | E21: Bananaquit (Coereba flaveola) | F21: Bananaquit | G21: song; Arenal Observatory Lodge, Fortuna, Costa Rica, 750 m | H21: B | I21: La Selva species | J21: =HYPERLINK("https://xeno-canto.org/331385","Open on Xeno-canto") -> Open on Xeno-canto
A22: XC331386.mp3 | B22: xc_flac | C22: 2016-07-26 | D22: 07:00 | E22: Bananaquit (Coereba flaveola) | F22: Bananaquit | G22: song; Arenal Observatory Lodge, Fortuna, Costa Rica, 750 m | H22: B | I22: La Selva species | J22: =HYPERLINK("https://xeno-canto.org/331386","Open on Xeno-canto") -> Open on Xeno-canto
A23: XC331387.mp3 | B23: xc_flac | C23: 2016-07-27 | D23: 09:00 | E23: Bananaquit (Coereba flaveola) | F23: Bananaquit | G23: song; Arenal Observatory Lodge, Fortuna, Costa Rica, 750 m | H23: B | I23: La Selva species | J23: =HYPERLINK("https://xeno-canto.org/331387","Open on Xeno-canto") -> Open on Xeno-canto
A24: XC331388.mp3 | B24: xc_flac | C24: 2016-07-26 | D24: 06:00 | E24: Black-throated Wren (Pheugopedius atrogularis) | F24: Black-throated Wren | G24: song; Arenal Observatory Lodge, Fortuna, Costa Rica, 750 m | H24: B | I24: La Selva species | J24: =HYPERLINK("https://xeno-canto.org/331388","Open on Xeno-canto") -> Open on Xeno-canto
A25: XC331389.mp3 | B25: xc_flac | C25: 2016-07-26 | D25: 06:00 | E25: Black-throated Wren (Pheugopedius atrogularis) | F25: Black-throated Wren | G25: song; Arenal Observatory Lodge, Fortuna, Costa Rica, 750 m | H25: B | I25: La Selva species | J25: =HYPERLINK("https://xeno-canto.org/331389","Open on Xeno-canto") -> Open on Xeno-canto
A26: XC331390.mp3 | B26: xc_flac | C26: 2016-07-26 | D26: 15:30 | E26: Cinnamon Becard (Pachyramphus cinnamomeus) | F26: Cinnamon Becard | G26: song; Arenal Observatory Lodge, Fortuna, Costa Rica, 750 m | H26: B | I26: La Selva species | J26: =HYPERLINK("https://xeno-canto.org/331390","Open on Xeno-canto") -> Open on Xeno-canto
A27: XC331431.mp3 | B27: xc_flac | C27: 2016-07-26 | D27: 07:00 | E27: Clay-colored Thrush (Turdus grayi) | F27: Clay-colored Thrush | G27: song; Arenal Observatory Lodge, Fortuna, Costa Rica, 750 m | H27: B | I27: La Selva species | J27: =HYPERLINK("https://xeno-canto.org/331431","Open on Xeno-canto") -> Open on Xeno-canto
A28: XC331434.mp3 | B28: xc_flac | C28: 2016-07-26 | D28: 16:30 | E28: Black-striped Sparrow (Arremonops conirostris) | F28: Black-striped Sparrow | G28: song; Arenal Observatory Lodge, Fortuna, Costa Rica, 750 m | H28: B | I28: La Selva species | J28: =HYPERLINK("https://xeno-canto.org/331434","Open on Xeno-canto") -> Open on Xeno-canto
A29: XC331436.mp3 | B29: xc_flac | C29: 2016-07-26 | D29: 16:00 | E29: Scaly-breasted Hummingbird (Phaeochroa cuvierii) | F29: Scaly-breasted Hummingbird | G29: song; Arenal Observatory Lodge, Fortuna, Costa Rica, 750 m | H29: A | I29: La Selva species | J29: =HYPERLINK("https://xeno-canto.org/331436","Open on Xeno-canto") -> Open on Xeno-canto
A30: XC331449.mp3 | B30: xc_flac | C30: 2016-07-26 | D30: 17:30 | E30: Common Tody-Flycatcher (Todirostrum cinereum) | F30: Common Tody-Flycatcher | G30: call; Arenal Observatory Lodge, Fortuna, Costa Rica, 750 m | H30: B | I30: La Selva species | J30: =HYPERLINK("https://xeno-canto.org/331449","Open on Xeno-canto") -> Open on Xeno-canto
A31: XC331460.mp3 | B31: xc_flac | C31: 2016-07-27 | D31: 06:00 | E31: Grey-capped Flycatcher (Myiozetetes granadensis) | F31: Gray-capped Flycatcher | G31: call; Arenal Observatory Lodge, Fortuna, Costa Rica, 750 m | H31: B | I31: La Selva species | J31: =HYPERLINK("https://xeno-canto.org/331460","Open on Xeno-canto") -> Open on Xeno-canto
A32: XC331462.mp3 | B32: xc_flac | C32: 2016-07-27 | D32: 09:30 | E32: Scarlet-rumped Tanager (Ramphocelus passerinii) | F32: Scarlet-rumped Tanager | G32: song; Arenal Observatory Lodge, Fortuna, Costa Rica, 750 m | H32: B | I32: La Selva species | J32: =HYPERLINK("https://xeno-canto.org/331462","Open on Xeno-canto") -> Open on Xeno-canto
A33: XC331463.mp3 | B33: xc_flac | C33: 2016-07-27 | D33: 10:00 | E33: Buff-rumped Warbler (Myiothlypis fulvicauda) | F33: Buff-rumped Warbler | G33: song; Arenal Observatory Lodge, Fortuna, Costa Rica, 750 m | H33: C | I33: La Selva species | J33: =HYPERLINK("https://xeno-canto.org/331463","Open on Xeno-canto") -> Open on Xeno-canto
A34: XC331465.mp3 | B34: xc_flac | C34: 2016-07-27 | D34: 11:00 | E34: Stripe-breasted Wren (Cantorchilus thoracicus) | F34: Stripe-breasted Wren | G34: song; Arenal Observatory Lodge, Fortuna, Costa Rica, 750 m | H34: A | I34: La Selva species | J34: =HYPERLINK("https://xeno-canto.org/331465","Open on Xeno-canto") -> Open on Xeno-canto
A35: XC331469.mp3 | B35: xc_flac | C35: 2016-07-26 | D35: 07:00 | E35: Streak-headed Woodcreeper (Lepidocolaptes souleyetii) | F35: Streak-headed Woodcreeper | G35: song; Arenal Observatory Lodge, Fortuna, Costa Rica, 750 m | H35: C | I35: La Selva species | J35: =HYPERLINK("https://xeno-canto.org/331469","Open on Xeno-canto") -> Open on Xeno-canto
A36: XC331470.mp3 | B36: xc_flac | C36: 2016-07-26 | D36: 06:30 | E36: Black-striped Sparrow (Arremonops conirostris) | F36: Black-striped Sparrow | G36: call; Arenal Observatory Lodge, Fortuna, Costa Rica, 750 m | H36: C | I36: La Selva species | J36: =HYPERLINK("https://xeno-canto.org/331470","Open on Xeno-canto") -> Open on Xeno-canto
A37: XC331600.mp3 | B37: xc_flac | C37: 2016-07-26 | D37: 10:30 | E37: Spotted Antbird (Hylophylax naevioides) | F37: Spotted Antbird | G37: alarm call, call; Arenal Observatory Lodge, Fortuna, Costa Rica, 750 m | H37: C | I37: La Selva species | J37: =HYPERLINK("https://xeno-canto.org/331600","Open on Xeno-canto") -> Open on Xeno-canto
A38: XC331639.mp3 | B38: xc_flac | C38: 2016-07-28 | D38: 13:00 | E38: Grey-headed Chachalaca (Ortalis cinereiceps) | F38: Gray-headed Chachalaca | G38: alarm call; Hotel El Bosque, Monteverde, Puntarenas, 1400 m | H38: C | I38: La Selva species | J38: =HYPERLINK("https://xeno-canto.org/331639","Open on Xeno-canto") -> Open on Xeno-canto
A39: XC331640.mp3 | B39: xc_flac | C39: 2016-07-27 | D39: 17:30 | E39: Montezuma Oropendola (Psarocolius montezuma) | F39: Montezuma Oropendola | G39: song; Hotel Castillo del Arenal, El Castillo, 600 m | H39: C | I39: La Selva species | J39: =HYPERLINK("https://xeno-canto.org/331640","Open on Xeno-canto") -> Open on Xeno-canto
A40: XC331641.mp3 | B40: xc_flac | C40: 2016-07-27 | D40: 17:30 | E40: Red-lored Amazon (Amazona autumnalis) | F40: Red-lored Amazon | G40: call; Hotel Castillo del Arenal, El Castillo, 600 m | H40: B | I40: La Selva species | J40: =HYPERLINK("https://xeno-canto.org/331641","Open on Xeno-canto") -> Open on Xeno-canto
...

Sheet Converted Clips
A1: Converted clips on the LaCie (xc_flac/, censused 2026-09-17)
A2: Every downloaded recording, converted with scripts/convert_to_flac.py to 32 kHz mono 16-bit FLAC (Perch's input format) and listed in manifests/xc_set_2146.csv. Originals (mp3, 44.1/48 kHz) stay in xc/. Paths are on the LaCie; neither folder is tracked by git.
A4: File | B4: Species folder | C4: Duration (s) | D4: Format | E4: Path on LaCie | F4: Xeno-canto Link
A5: 32 kHz mono FLAC — 77 files
A6: XC331252.flac | B6: xc_flac | C6: 63.048 | D6: FLAC 32 kHz mono | E6: /Volumes/LaCie/bird-project/data-prep/xc_flac/xc_flac/XC331252.flac | F6: =HYPERLINK("https://xeno-canto.org/331252","Open on Xeno-canto") -> Open on Xeno-canto
A7: XC331311.flac | B7: xc_flac | C7: 27.037 | D7: FLAC 32 kHz mono | E7: /Volumes/LaCie/bird-project/data-prep/xc_flac/xc_flac/XC331311.flac | F7: =HYPERLINK("https://xeno-canto.org/331311","Open on Xeno-canto") -> Open on Xeno-canto
A8: XC331314.flac | B8: xc_flac | C8: 42.266 | D8: FLAC 32 kHz mono | E8: /Volumes/LaCie/bird-project/data-prep/xc_flac/xc_flac/XC331314.flac | F8: =HYPERLINK("https://xeno-canto.org/331314","Open on Xeno-canto") -> Open on Xeno-canto
A9: XC331320.flac | B9: xc_flac | C9: 73.224 | D9: FLAC 32 kHz mono | E9: /Volumes/LaCie/bird-project/data-prep/xc_flac/xc_flac/XC331320.flac | F9: =HYPERLINK("https://xeno-canto.org/331320","Open on Xeno-canto") -> Open on Xeno-canto
A10: XC331322.flac | B10: xc_flac | C10: 7.968 | D10: FLAC 32 kHz mono | E10: /Volumes/LaCie/bird-project/data-prep/xc_flac/xc_flac/XC331322.flac | F10: =HYPERLINK("https://xeno-canto.org/331322","Open on Xeno-canto") -> Open on Xeno-canto
A11: XC331323.flac | B11: xc_flac | C11: 67.992 | D11: FLAC 32 kHz mono | E11: /Volumes/LaCie/bird-project/data-prep/xc_flac/xc_flac/XC331323.flac | F11: =HYPERLINK("https://xeno-canto.org/331323","Open on Xeno-canto") -> Open on Xeno-canto
A12: XC331326.flac | B12: xc_flac | C12: 64.444 | D12: FLAC 32 kHz mono | E12: /Volumes/LaCie/bird-project/data-prep/xc_flac/xc_flac/XC331326.flac | F12: =HYPERLINK("https://xeno-canto.org/331326","Open on Xeno-canto") -> Open on Xeno-canto
A13: XC331328.flac | B13: xc_flac | C13: 29.1 | D13: FLAC 32 kHz mono | E13: /Volumes/LaCie/bird-project/data-prep/xc_flac/xc_flac/XC331328.flac | F13: =HYPERLINK("https://xeno-canto.org/331328","Open on Xeno-canto") -> Open on Xeno-canto
A14: XC331333.flac | B14: xc_flac | C14: 35.004 | D14: FLAC 32 kHz mono | E14: /Volumes/LaCie/bird-project/data-prep/xc_flac/xc_flac/XC331333.flac | F14: =HYPERLINK("https://xeno-canto.org/331333","Open on Xeno-canto") -> Open on Xeno-canto
A15: XC331334.flac | B15: xc_flac | C15: 37.538 | D15: FLAC 32 kHz mono | E15: /Volumes/LaCie/bird-project/data-prep/xc_flac/xc_flac/XC331334.flac | F15: =HYPERLINK("https://xeno-canto.org/331334","Open on Xeno-canto") -> Open on Xeno-canto
A16: XC331335.flac | B16: xc_flac | C16: 74.544 | D16: FLAC 32 kHz mono | E16: /Volumes/LaCie/bird-project/data-prep/xc_flac/xc_flac/XC331335.flac | F16: =HYPERLINK("https://xeno-canto.org/331335","Open on Xeno-canto") -> Open on Xeno-canto
A17: XC331336.flac | B17: xc_flac | C17: 35.396 | D17: FLAC 32 kHz mono | E17: /Volumes/LaCie/bird-project/data-prep/xc_flac/xc_flac/XC331336.flac | F17: =HYPERLINK("https://xeno-canto.org/331336","Open on Xeno-canto") -> Open on Xeno-canto
A18: XC331354.flac | B18: xc_flac | C18: 28.656 | D18: FLAC 32 kHz mono | E18: /Volumes/LaCie/bird-project/data-prep/xc_flac/xc_flac/XC331354.flac | F18: =HYPERLINK("https://xeno-canto.org/331354","Open on Xeno-canto") -> Open on Xeno-canto
A19: XC331355.flac | B19: xc_flac | C19: 52.176 | D19: FLAC 32 kHz mono | E19: /Volumes/LaCie/bird-project/data-prep/xc_flac/xc_flac/XC331355.flac | F19: =HYPERLINK("https://xeno-canto.org/331355","Open on Xeno-canto") -> Open on Xeno-canto
A20: XC331356.flac | B20: xc_flac | C20: 58.008 | D20: FLAC 32 kHz mono | E20: /Volumes/LaCie/bird-project/data-prep/xc_flac/xc_flac/XC331356.flac | F20: =HYPERLINK("https://xeno-canto.org/331356","Open on Xeno-canto") -> Open on Xeno-canto
A21: XC331362.flac | B21: xc_flac | C21: 56.52 | D21: FLAC 32 kHz mono | E21: /Volumes/LaCie/bird-project/data-prep/xc_flac/xc_flac/XC331362.flac | F21: =HYPERLINK("https://xeno-canto.org/331362","Open on Xeno-canto") -> Open on Xeno-canto
A22: XC331367.flac | B22: xc_flac | C22: 13.92 | D22: FLAC 32 kHz mono | E22: /Volumes/LaCie/bird-project/data-prep/xc_flac/xc_flac/XC331367.flac | F22: =HYPERLINK("https://xeno-canto.org/331367","Open on Xeno-canto") -> Open on Xeno-canto
A23: XC331372.flac | B23: xc_flac | C23: 43.128 | D23: FLAC 32 kHz mono | E23: /Volumes/LaCie/bird-project/data-prep/xc_flac/xc_flac/XC331372.flac | F23: =HYPERLINK("https://xeno-canto.org/331372","Open on Xeno-canto") -> Open on Xeno-canto
A24: XC331381.flac | B24: xc_flac | C24: 70.488 | D24: FLAC 32 kHz mono | E24: /Volumes/LaCie/bird-project/data-prep/xc_flac/xc_flac/XC331381.flac | F24: =HYPERLINK("https://xeno-canto.org/331381","Open on Xeno-canto") -> Open on Xeno-canto
A25: XC331385.flac | B25: xc_flac | C25: 31.44 | D25: FLAC 32 kHz mono | E25: /Volumes/LaCie/bird-project/data-prep/xc_flac/xc_flac/XC331385.flac | F25: =HYPERLINK("https://xeno-canto.org/331385","Open on Xeno-canto") -> Open on Xeno-canto
A26: XC331386.flac | B26: xc_flac | C26: 6 | D26: FLAC 32 kHz mono | E26: /Volumes/LaCie/bird-project/data-prep/xc_flac/xc_flac/XC331386.flac | F26: =HYPERLINK("https://xeno-canto.org/331386","Open on Xeno-canto") -> Open on Xeno-canto
A27: XC331387.flac | B27: xc_flac | C27: 9 | D27: FLAC 32 kHz mono | E27: /Volumes/LaCie/bird-project/data-prep/xc_flac/xc_flac/XC331387.flac | F27: =HYPERLINK("https://xeno-canto.org/331387","Open on Xeno-canto") -> Open on Xeno-canto
A28: XC331388.flac | B28: xc_flac | C28: 45.12 | D28: FLAC 32 kHz mono | E28: /Volumes/LaCie/bird-project/data-prep/xc_flac/xc_flac/XC331388.flac | F28: =HYPERLINK("https://xeno-canto.org/331388","Open on Xeno-canto") -> Open on Xeno-canto
A29: XC331389.flac | B29: xc_flac | C29: 6.624 | D29: FLAC 32 kHz mono | E29: /Volumes/LaCie/bird-project/data-prep/xc_flac/xc_flac/XC331389.flac | F29: =HYPERLINK("https://xeno-canto.org/331389","Open on Xeno-canto") -> Open on Xeno-canto
A30: XC331390.flac | B30: xc_flac | C30: 33.888 | D30: FLAC 32 kHz mono | E30: /Volumes/LaCie/bird-project/data-prep/xc_flac/xc_flac/XC331390.flac | F30: =HYPERLINK("https://xeno-canto.org/331390","Open on Xeno-canto") -> Open on Xeno-canto
A31: XC331431.flac | B31: xc_flac | C31: 65.568 | D31: FLAC 32 kHz mono | E31: /Volumes/LaCie/bird-project/data-prep/xc_flac/xc_flac/XC331431.flac | F31: =HYPERLINK("https://xeno-canto.org/331431","Open on Xeno-canto") -> Open on Xeno-canto
A32: XC331434.flac | B32: xc_flac | C32: 45.552 | D32: FLAC 32 kHz mono | E32: /Volumes/LaCie/bird-project/data-prep/xc_flac/xc_flac/XC331434.flac | F32: =HYPERLINK("https://xeno-canto.org/331434","Open on Xeno-canto") -> Open on Xeno-canto
A33: XC331436.flac | B33: xc_flac | C33: 39.768 | D33: FLAC 32 kHz mono | E33: /Volumes/LaCie/bird-project/data-prep/xc_flac/xc_flac/XC331436.flac | F33: =HYPERLINK("https://xeno-canto.org/331436","Open on Xeno-canto") -> Open on Xeno-canto
A34: XC331449.flac | B34: xc_flac | C34: 15.024 | D34: FLAC 32 kHz mono | E34: /Volumes/LaCie/bird-project/data-prep/xc_flac/xc_flac/XC331449.flac | F34: =HYPERLINK("https://xeno-canto.org/331449","Open on Xeno-canto") -> Open on Xeno-canto
A35: XC331460.flac | B35: xc_flac | C35: 16.824 | D35: FLAC 32 kHz mono | E35: /Volumes/LaCie/bird-project/data-prep/xc_flac/xc_flac/XC331460.flac | F35: =HYPERLINK("https://xeno-canto.org/331460","Open on Xeno-canto") -> Open on Xeno-canto
A36: XC331462.flac | B36: xc_flac | C36: 13.056 | D36: FLAC 32 kHz mono | E36: /Volumes/LaCie/bird-project/data-prep/xc_flac/xc_flac/XC331462.flac | F36: =HYPERLINK("https://xeno-canto.org/331462","Open on Xeno-canto") -> Open on Xeno-canto
A37: XC331463.flac | B37: xc_flac | C37: 7.968 | D37: FLAC 32 kHz mono | E37: /Volumes/LaCie/bird-project/data-prep/xc_flac/xc_flac/XC331463.flac | F37: =HYPERLINK("https://xeno-canto.org/331463","Open on Xeno-canto") -> Open on Xeno-canto
A38: XC331465.flac | B38: xc_flac | C38: 10.176 | D38: FLAC 32 kHz mono | E38: /Volumes/LaCie/bird-project/data-prep/xc_flac/xc_flac/XC331465.flac | F38: =HYPERLINK("https://xeno-canto.org/331465","Open on Xeno-canto") -> Open on Xeno-canto
A39: XC331469.flac | B39: xc_flac | C39: 43.824 | D39: FLAC 32 kHz mono | E39: /Volumes/LaCie/bird-project/data-prep/xc_flac/xc_flac/XC331469.flac | F39: =HYPERLINK("https://xeno-canto.org/331469","Open on Xeno-canto") -> Open on Xeno-canto
A40: XC331470.flac | B40: xc_flac | C40: 27.552 | D40: FLAC 32 kHz mono | E40: /Volumes/LaCie/bird-project/data-prep/xc_flac/xc_flac/XC331470.flac | F40: =HYPERLINK("https://xeno-canto.org/331470","Open on Xeno-canto") -> Open on Xeno-canto
A41: XC331600.flac | B41: xc_flac | C41: 10.584 | D41: FLAC 32 kHz mono | E41: /Volumes/LaCie/bird-project/data-prep/xc_flac/xc_flac/XC331600.flac | F41: =HYPERLINK("https://xeno-canto.org/331600","Open on Xeno-canto") -> Open on Xeno-canto
...
