Workbook

Sheet Species Summary
A1: Costa Rica Site Data — Species Summary
A2: Existing labeled/extracted recordings from the 2022 AudioMoth deployment at La Selva Biological Station (folder: 2022-Jume-18_RegularMoth4_forest). Site data only — before any Xeno-canto or other public data.
A3: =HYPERLINK("https://drive.google.com/drive/folders/1z8aF21SAkHmx80vnpkARR_O1ZN8tR-4q","Open source Drive folder") -> Open source Drive folder
A5: Species | B5: Scientific name | C5: # Recordings | D5: Data notes | E5: Recording 1 | F5: Recording 2 | G5: Recording 3 | H5: Recording 4 | I5: Recording 5 | J5: Recording 6 | K5: Recording 7 | L5: Recording 8 | M5: Recording 9 | N5: Recording 10 | O5: Recording 11 | P5: Recording 12 | Q5: Recording 13 | R5: Recording 14 | S5: Recording 15 | T5: Recording 16 | U5: Recording 17
A6: BIRDS — 16 species identified at the site (44 labeled bird recordings; all extracts labeled)
A7: White-breasted Wood-Wren | B7: Henicorhina leucosticta | C7: =COUNTIF('All Recordings'!$F$2:$F$65,"*White-breasted Wood-Wren*") -> 17 | D7: Best-covered species, both days; includes 1 duplicate pair (Bird 12/13), 1 partial, 2 filename-labeled cuts | E7: =HYPERLINK("https://drive.google.com/file/d/1Ph30uo9N5juiSDqbCtfE5uVHUYuCKU2M/view","Bird 12 (June 18)") -> Bird 12 (June 18) | F7: =HYPERLINK("https://drive.google.com/file/d/1LvbwVMJSpY5jFOaFXA3jeoTf49hpxVyJ/view","Bird 13 (June 18)") -> Bird 13 (June 18) | G7: =HYPERLINK("https://drive.google.com/file/d/1OS_MC9AClW2o7uiAbNizmeUIM8YOk-ME/view","Bird 14 (June 18)") -> Bird 14 (June 18) | H7: =HYPERLINK("https://drive.google.com/file/d/1QqkobA0-Lc4BINRmcrwGLjIhdT763Zyz/view","Bird 15 (June 18)") -> Bird 15 (June 18) | I7: =HYPERLINK("https://drive.google.com/file/d/1OXZFPhXO1LgFl3th7S50pZVXMDHBMPTw/view","Bird 18 (June 18)") -> Bird 18 (June 18) | J7: =HYPERLINK("https://drive.google.com/file/d/1R5BJDlpF1thNjqQgqqBeEDpiMgxUGm6v/view","Bird 20 (June 18)") -> Bird 20 (June 18) | K7: =HYPERLINK("https://drive.google.com/file/d/1PhLzPtk__JKJogT9oN79sUfwx0JfjITz/view","Bird 23 (June 18)") -> Bird 23 (June 18) | L7: =HYPERLINK("https://drive.google.com/file/d/1LrxnHJzhh5qmOYFqXtn9fI__56GlW5Xt/view","Bird 27 (June 18)") -> Bird 27 (June 18) | M7: =HYPERLINK("https://drive.google.com/file/d/1QUBq0yZBayf-qcmUTpUNqbKkgwxWlQcR/view","Bird 34 (June 18)") -> Bird 34 (June 18) | N7: =HYPERLINK("https://drive.google.com/file/d/1Qv_nkcoFKxVy1IBnttHjFCPico1twY7v/view","Bird 39 (June 18)") -> Bird 39 (June 18) | O7: =HYPERLINK("https://drive.google.com/file/d/1NP93wRtaAaKQ7bc9oz67Jlx7W5FeIdPc/view","Bird 40 (June 18)") -> Bird 40 (June 18) | P7: =HYPERLINK("https://drive.google.com/file/d/1Pdak2ABC1pdXnWuGrIDdbvrtHIb5_PYc/view","20220601_000000_wb wren (June 18)") -> 20220601_000000_wb wren (June 18) | Q7: =HYPERLINK("https://drive.google.com/file/d/1Q0A4vLRAdI6mQLwBmkFzxUuEqfXCWdDS/view","20220601_000000_wb wren v2 (June 18)") -> 20220601_000000_wb wren v2 (June 18) | R7: =HYPERLINK("https://drive.google.com/file/d/1MWzw36_cmZLLiT1hGwv6ZcytA7OpsaR_/view","Bird 42 (June 18)") -> Bird 42 (June 18) | S7: =HYPERLINK("https://drive.google.com/file/d/1KslMZnTM4gRy19XP12qYwdDKzsKcI6CC/view","Bird 1 (June 17)") -> Bird 1 (June 17) | T7: =HYPERLINK("https://drive.google.com/file/d/1L54PpyWBP3mlVJ1n8Ok-ofucroo4P7f4/view","Bird 3 (June 17)") -> Bird 3 (June 17) | U7: =HYPERLINK("https://drive.google.com/file/d/1LXATZi4KrYbpoSzRUUB9-uq4k1xPkEj9/view","Bird 4 (June 17)") -> Bird 4 (June 17)
A8: Great Tinamou | B8: Tinamus major | C8: =COUNTIF('All Recordings'!$F$2:$F$65,"*Great Tinamou*") -> 4 | D8: Bird 1 and June 17 Bird 6 are solos; other 2 are uncertain/mixed | E8: =HYPERLINK("https://drive.google.com/file/d/1OLWgL-ozIaPw9gmSt2KbrXVLhmRgwsN6/view","Bird 1 (June 18)") -> Bird 1 (June 18) | F8: =HYPERLINK("https://drive.google.com/file/d/1OY-WA3n0_QCTuOpvgbACXfN0KXTtswxq/view","Bird 19 (June 18)") -> Bird 19 (June 18) | G8: =HYPERLINK("https://drive.google.com/file/d/1QUBq0yZBayf-qcmUTpUNqbKkgwxWlQcR/view","Bird 34 (June 18)") -> Bird 34 (June 18) | H8: =HYPERLINK("https://drive.google.com/file/d/1KtQ7Yj7q43tU2lDgl8GlAoagkYVgGPhn/view","Bird 6 (June 17)") -> Bird 6 (June 17)
A9: Yellow-throated Toucan | B9: Ramphastos ambiguus | C9: =COUNTIF('All Recordings'!$F$2:$F$65,"*Yellow-throated Toucan*") -> 4 | D9: One recording uncertain (Bird 19, mixed with tinamou) | E9: =HYPERLINK("https://drive.google.com/file/d/1Q7Wnzi5nPYZxjBQw_UVV66coNOw_Q103/view","Bird 16 (June 18)") -> Bird 16 (June 18) | F9: =HYPERLINK("https://drive.google.com/file/d/1OY-WA3n0_QCTuOpvgbACXfN0KXTtswxq/view","Bird 19 (June 18)") -> Bird 19 (June 18) | G9: =HYPERLINK("https://drive.google.com/file/d/1LcqhEZ_t2VLNPm0QelcUh-Ybnwzjia9S/view","Bird 21 (June 18)") -> Bird 21 (June 18) | H9: =HYPERLINK("https://drive.google.com/file/d/1NEmCYDzlcH7dpiFoRjCPwuOitRrtrBDz/view","Bird 22 (June 18)") -> Bird 22 (June 18)
A10: Green Ibis | B10: Mesembrinibis cayennensis | C10: =COUNTIF('All Recordings'!$F$2:$F$65,"*Green Ibis*") -> 3 | D10: Bird 7 overlaps a motmot call | E10: =HYPERLINK("https://drive.google.com/file/d/1PTf7yxHUFUPr7xcm0rpVJ0oVRyrN3l9a/view","Bird 2 (June 18)") -> Bird 2 (June 18) | F10: =HYPERLINK("https://drive.google.com/file/d/1R5GoR5zDhvgnwl9HiltF3F69JuFsIi-x/view","Bird 3 (June 18)") -> Bird 3 (June 18) | G10: =HYPERLINK("https://drive.google.com/file/d/1Lj4AhqhgrC6NLnIM5cWfFpkcMOvLgFLJ/view","Bird 7 (June 18)") -> Bird 7 (June 18)
A11: Broad-billed Motmot | B11: Electron platyrhynchum | C11: =COUNTIF('All Recordings'!$F$2:$F$65,"*Broad-billed Motmot*") -> 3 | D11: Bird 8 overlaps an ibis call | E11: =HYPERLINK("https://drive.google.com/file/d/1N0hh-DcQUJqNcyiLik9hi1A2VhCdALJe/view","Bird 8 (June 18)") -> Bird 8 (June 18) | F11: =HYPERLINK("https://drive.google.com/file/d/1MEkqIrIWhF_0mYMOsXNOzAIh9pgjU3Gl/view","Bird 9 (June 18)") -> Bird 9 (June 18) | G11: =HYPERLINK("https://drive.google.com/file/d/1R9JBAbCcuDfomerQa4jeznZIlucukwev/view","Bird 25 (June 18)") -> Bird 25 (June 18)
A12: Mealy Parrot | B12: Amazona farinosa | C12: =COUNTIF('All Recordings'!$F$2:$F$65,"*Mealy Parrot*") -> 3 | E12: =HYPERLINK("https://drive.google.com/file/d/1ObGDqOUup6sxeMNzDhu8nbJHMGqUlC_r/view","Bird 26 (June 18)") -> Bird 26 (June 18) | F12: =HYPERLINK("https://drive.google.com/file/d/1Ol_wa-unD9U-uJHWGHcVehBqKP3AVeRi/view","Bird 28 (June 18)") -> Bird 28 (June 18) | G12: =HYPERLINK("https://drive.google.com/file/d/1MMDv4CjtGOm8sMvkfMogyWiADOA3w6eA/view","Bird 37 (June 18)") -> Bird 37 (June 18)
A13: Lesser Greenlet | B13: Pachysylvia decurtata | C13: =COUNTIF('All Recordings'!$F$2:$F$65,"*Lesser Greenlet*") -> 2 | E13: =HYPERLINK("https://drive.google.com/file/d/1MhCNjxmYrH5vqJ3vfYqC7l6w47aL8lBw/view","Bird 36 (June 18)") -> Bird 36 (June 18) | F13: =HYPERLINK("https://drive.google.com/file/d/1NE9GBfwap16oD5vnRI_UBifaTvNuQgbP/view","Bird 41 (June 18)") -> Bird 41 (June 18)
A14: Northern Barred-Woodcreeper | B14: Dendrocolaptes sanctithomae | C14: =COUNTIF('All Recordings'!$F$2:$F$65,"*Northern Barred-Woodcreeper*") -> 2 | E14: =HYPERLINK("https://drive.google.com/file/d/1OUogRQYoSpr4TWydvvpZiuw8eAWS67p1/view","Bird 10 (June 18)") -> Bird 10 (June 18) | F14: =HYPERLINK("https://drive.google.com/file/d/1O8C_t3_fUO9Lc-cPBDkr7nq4tkvbUBE6/view","Bird 30 (June 18)") -> Bird 30 (June 18)
A15: Rufous Motmot | B15: Baryphthengus martii | C15: =COUNTIF('All Recordings'!$F$2:$F$65,"*Rufous Motmot*") -> 2 | E15: =HYPERLINK("https://drive.google.com/file/d/1OGzS2JhE_aVyrJFDGJCtSQLqqcHzZsl6/view","Bird 11 (June 18)") -> Bird 11 (June 18) | F15: =HYPERLINK("https://drive.google.com/file/d/1OOWY7xhMNbjtVmDrcX8NtDIz72P5eL9-/view","Bird 33 (June 18)") -> Bird 33 (June 18)
A16: Red-lored Parrot | B16: Amazona autumnalis | C16: =COUNTIF('All Recordings'!$F$2:$F$65,"*Red-lored Parrot*") -> 2 | D16: Both recordings flagged 'Multiple birds?' in the log | E16: =HYPERLINK("https://drive.google.com/file/d/1QUBq0yZBayf-qcmUTpUNqbKkgwxWlQcR/view","Bird 34 (June 18)") -> Bird 34 (June 18) | F16: =HYPERLINK("https://drive.google.com/file/d/1LyW8nNstobehi41CbZky7DBb4_F8QqEG/view","Bird 35 (June 18)") -> Bird 35 (June 18)
A17: Great Green Macaw | B17: Ara ambiguus | C17: =COUNTIF('All Recordings'!$F$2:$F$65,"*Great Green Macaw*") -> 1 | D17: NO clean solo recording — only an overlap with a wood-wren (Bird 15) | E17: =HYPERLINK("https://drive.google.com/file/d/1QqkobA0-Lc4BINRmcrwGLjIhdT763Zyz/view","Bird 15 (June 18)") -> Bird 15 (June 18)
A18: Chestnut-backed Antbird | B18: Poliocrania exsul | C18: =COUNTIF('All Recordings'!$F$2:$F$65,"*Chestnut-backed Antbird*") -> 1 | D18: Extract contains a second call at 11:42:09 | E18: =HYPERLINK("https://drive.google.com/file/d/1Q3SymxnsfEBVVUt5V9N8nxZi8HdgpL-o/view","Bird 38 (June 18)") -> Bird 38 (June 18)
A19: Chestnut-headed Oropendola | B19: Psarocolius wagleri | C19: =COUNTIF('All Recordings'!$F$2:$F$65,"*Chestnut-headed Oropendola*") -> 1 | D19: Single UNCERTAIN recording — log note 'Maybe oropendola?' | E19: =HYPERLINK("https://drive.google.com/file/d/1M-t9UjFkR_aaUAtqHSm64Tkhf77xvqqs/view","Bird 7 (June 17)") -> Bird 7 (June 17)
A20: Black-striped Woodcreeper | B20: Xiphorhynchus lachrymosus | C20: =COUNTIF('All Recordings'!$F$2:$F$65,"*Black-striped Woodcreeper*") -> 1 | D20: Log note: 'Unique call' | E20: =HYPERLINK("https://drive.google.com/file/d/1LLffGFQxgmunF67n6O_vL_wvlSCQ5ITb/view","Bird 9 (June 17)") -> Bird 9 (June 17)
A21: Scarlet-rumped Cacique | B21: Cacicus uropygialis | C21: =COUNTIF('All Recordings'!$F$2:$F$65,"*Scarlet-rumped Cacique*") -> 1 | E21: =HYPERLINK("https://drive.google.com/file/d/1OekFxn0YyLfJ88QXhU_ZpSXyuEwBmBmd/view","Bird 31 (June 18)") -> Bird 31 (June 18)
A22: Stripe-breasted Wren | B22: Cantorchilus thoracicus | C22: =COUNTIF('All Recordings'!$F$2:$F$65,"*Stripe-breasted Wren*") -> 1 | E22: =HYPERLINK("https://drive.google.com/file/d/1MJSD7Dg_wFW1I9ivrngTp4iqqh7l71Tx/view","Bird 32 (June 18)") -> Bird 32 (June 18)
A23: NON-BIRD SOUNDS captured in the extracts (useful as negative examples)
A24: Frogs (all) | C24: =COUNTIF('All Recordings'!$F$2:$F$65,"*Frog*") -> 17 | D24: Pristimantis, Scinax, Craugastor, Dendropsophus, Leptodactylus + 6 misfiled as 'Bird' | E24: =HYPERLINK("https://drive.google.com/file/d/1QjoOyggvPph1RYP9LO2EZnQErt6maAWX/view","Bird 17 (June 18)") -> Bird 17 (June 18) | F24: =HYPERLINK("https://drive.google.com/file/d/1LmrehfnxZCSubakCx8HpG_Awc18BQXug/view","Bird 24 (June 18)") -> Bird 24 (June 18) | G24: =HYPERLINK("https://drive.google.com/file/d/1OoB_BHni35y9fuHFXVEgJ3JTEes4_xak/view","Frog 1 (June 18)") -> Frog 1 (June 18) | H24: =HYPERLINK("https://drive.google.com/file/d/1PiBSrioOqjePkI2iYAavq8vj_FTTH2D-/view","Frog 2 (June 18)") -> Frog 2 (June 18) | I24: =HYPERLINK("https://drive.google.com/file/d/1L_LLl5qV2wyp6j25I_Bla-CfrQlbi5I3/view","Frog 3 (June 18)") -> Frog 3 (June 18) | J24: =HYPERLINK("https://drive.google.com/file/d/1QDiJtr_0ERxtQ5-TqA9cHJxeEItP01VW/view","Frog 4 (June 18)") -> Frog 4 (June 18) | K24: =HYPERLINK("https://drive.google.com/file/d/1Qj62a__PHggWmUFc23SNPHJQJLmlWki-/view","Frog 5 (June 18)") -> Frog 5 (June 18) | L24: =HYPERLINK("https://drive.google.com/file/d/1P0ezjnvvlN9fPdv0gadhju4Q-f1Bdumc/view","Frog 6 (June 18)") -> Frog 6 (June 18) | M24: =HYPERLINK("https://drive.google.com/file/d/1PUBRK_T1IHGD3L70xF5jPLUpO4UTAqga/view","Frog 7 (June 18)") -> Frog 7 (June 18) | N24: =HYPERLINK("https://drive.google.com/file/d/1POm-4Dt3M_BBI8rBVFtyLbpp7YB3qpF5/view","Frog 8 (June 18)") -> Frog 8 (June 18) | O24: =HYPERLINK("https://drive.google.com/file/d/1QbxU3MmHvJWMjcO2Z-287jnRod19ZdFn/view","Frog 9 (June 18)") -> Frog 9 (June 18) | P24: =HYPERLINK("https://drive.google.com/file/d/1MGQTLTs8LeYT0kYk4d765JLzdAgDDwSW/view","Frog 10 (June 18)") -> Frog 10 (June 18) | Q24: =HYPERLINK("https://drive.google.com/file/d/1MbNsb5RW2_REXxJ_aaQk65yYh_795kRk/view","Frog 11 (June 18)") -> Frog 11 (June 18) | R24: =HYPERLINK("https://drive.google.com/file/d/1LRwHEqyJaPtOTMNTp3c81H4rW7EzRjZh/view","BIrd 2 (June 17)") -> BIrd 2 (June 17) | S24: =HYPERLINK("https://drive.google.com/file/d/1L56X-kS23x0qYo9I5KaID6YXRMdVddGR/view","Bird 8 (June 17)") -> Bird 8 (June 17) | T24: =HYPERLINK("https://drive.google.com/file/d/1LMX7tyZq5C7oRwhZEaUHeyngz5raumqr/view","Bird 10 (June 17)") -> Bird 10 (June 17) | U24: =HYPERLINK("https://drive.google.com/file/d/1KoiGQC9QjiztyDOrzdXm5NWurbJ9ktoW/view","Bird 11 (June 17)") -> Bird 11 (June 17)
A25: Spider Monkey | B25: Ateles geoffroyi | C25: =COUNTIF('All Recordings'!$F$2:$F$65,"*Spider Monkey*") -> 1 | D25: Misfiled as 'Bird 6' in the log | E25: =HYPERLINK("https://drive.google.com/file/d/1NTWYCaxeNt_6DnJo-cNppForrrKF4gr1/view","Bird 6 (June 18)") -> Bird 6 (June 18)
A26: Insects (all) | B26: — | C26: =COUNTIF('All Recordings'!$F$2:$F$65,"*Insect*") -> 2 | D26: Cicada? (June 18 Bird 29) and cricket (June 17 Bird 5), misfiled as 'Bird' | E26: =HYPERLINK("https://drive.google.com/file/d/1QPrguGf9v5ZcVYAa6datE5E7VLwba80-/view","Bird 29 (June 18)") -> Bird 29 (June 18) | F26: =HYPERLINK("https://drive.google.com/file/d/1L4GdU1ynSLFDBfu4hrxEuO6ywWPumBkP/view","Bird 5 (June 17)") -> Bird 5 (June 17)

Sheet All Recordings
A1: File | B1: Folder | C1: Date | D1: UTC Time | E1: Label (as written in log) | F1: Species (canonical) | G1: Notes | H1: Status | I1: Drive Link
A2: Bird 1.wav | B2: June 18 | C2: 2022-06-18 | D2: 0:09:52 | E2: Great tinamou | F2: Great Tinamou | H2: Labeled | I2: =HYPERLINK("https://drive.google.com/file/d/1OLWgL-ozIaPw9gmSt2KbrXVLhmRgwsN6/view","Open in Drive") -> Open in Drive
A3: Bird 2.wav | B3: June 18 | C3: 2022-06-18 | D3: 0:13:39 | E3: Green Ibis | F3: Green Ibis | G3: Multi-band, includes crickets | H3: Labeled | I3: =HYPERLINK("https://drive.google.com/file/d/1PTf7yxHUFUPr7xcm0rpVJ0oVRyrN3l9a/view","Open in Drive") -> Open in Drive
A4: Bird 3.wav | B4: June 18 | C4: 2022-06-18 | D4: 0:16:53 | E4: Green Ibis | F4: Green Ibis | H4: Labeled | I4: =HYPERLINK("https://drive.google.com/file/d/1R5GoR5zDhvgnwl9HiltF3F69JuFsIi-x/view","Open in Drive") -> Open in Drive
A5: Bird 6.wav | B5: June 18 | C5: 2022-06-18 | D5: 10:55:38 | E5: Spider monkey | F5: Spider Monkey | G5: Not a bird (labeled 'Monkey' in log) | H5: Non-bird | I5: =HYPERLINK("https://drive.google.com/file/d/1NTWYCaxeNt_6DnJo-cNppForrrKF4gr1/view","Open in Drive") -> Open in Drive
A6: Bird 7.wav | B6: June 18 | C6: 2022-06-18 | D6: 10:58:35 | E6: Green Ibis | F6: Green Ibis | G6: Overlaps with Bird 8 | H6: Labeled | I6: =HYPERLINK("https://drive.google.com/file/d/1Lj4AhqhgrC6NLnIM5cWfFpkcMOvLgFLJ/view","Open in Drive") -> Open in Drive
A7: Bird 8.wav | B7: June 18 | C7: 2022-06-18 | D7: 10:58:47 | E7: Broad-billed Motmot | F7: Broad-billed Motmot | G7: Overlaps with Bird 7 | H7: Labeled | I7: =HYPERLINK("https://drive.google.com/file/d/1N0hh-DcQUJqNcyiLik9hi1A2VhCdALJe/view","Open in Drive") -> Open in Drive
A8: Bird 9.wav | B8: June 18 | C8: 2022-06-18 | D8: 11:02:10 | E8: Broad-billed Motmot | F8: Broad-billed Motmot | H8: Labeled | I8: =HYPERLINK("https://drive.google.com/file/d/1MEkqIrIWhF_0mYMOsXNOzAIh9pgjU3Gl/view","Open in Drive") -> Open in Drive
A9: Bird 10.wav | B9: June 18 | C9: 2022-06-18 | D9: 11:02:37 | E9: Northern barred woodcreeper | F9: Northern Barred-Woodcreeper | H9: Labeled | I9: =HYPERLINK("https://drive.google.com/file/d/1OUogRQYoSpr4TWydvvpZiuw8eAWS67p1/view","Open in Drive") -> Open in Drive
A10: Bird 11.wav | B10: June 18 | C10: 2022-06-18 | D10: 11:05:43 | E10: Rufous Motmot | F10: Rufous Motmot | H10: Labeled | I10: =HYPERLINK("https://drive.google.com/file/d/1OGzS2JhE_aVyrJFDGJCtSQLqqcHzZsl6/view","Open in Drive") -> Open in Drive
A11: Bird 12.wav | B11: June 18 | C11: 2022-06-18 | D11: 11:10:02 | E11: White breasted wood wren | F11: White-breasted Wood-Wren | G11: Same call as Bird 13 (duplicate) | H11: Labeled | I11: =HYPERLINK("https://drive.google.com/file/d/1Ph30uo9N5juiSDqbCtfE5uVHUYuCKU2M/view","Open in Drive") -> Open in Drive
A12: Bird 13.wav | B12: June 18 | C12: 2022-06-18 | D12: 11:10:03 | E12: White breasted wood wren | F12: White-breasted Wood-Wren | G12: Same call as Bird 12 (duplicate) | H12: Labeled | I12: =HYPERLINK("https://drive.google.com/file/d/1LvbwVMJSpY5jFOaFXA3jeoTf49hpxVyJ/view","Open in Drive") -> Open in Drive
A13: Bird 14.wav | B13: June 18 | C13: 2022-06-18 | D13: 11:10:13 | E13: White breasted wood wren | F13: White-breasted Wood-Wren | G13: Partial extract | H13: Labeled | I13: =HYPERLINK("https://drive.google.com/file/d/1OS_MC9AClW2o7uiAbNizmeUIM8YOk-ME/view","Open in Drive") -> Open in Drive
A14: Bird 15.wav | B14: June 18 | C14: 2022-06-18 | D14: 11:11:02 | E14: Green macaw & white breasted wood wren | F14: Great Green Macaw; White-breasted Wood-Wren | G14: Two species overlap | H14: Labeled | I14: =HYPERLINK("https://drive.google.com/file/d/1QqkobA0-Lc4BINRmcrwGLjIhdT763Zyz/view","Open in Drive") -> Open in Drive
A15: Bird 16.wav | B15: June 18 | C15: 2022-06-18 | D15: 11:11:46 | E15: Yellow-throated toucan | F15: Yellow-throated Toucan | H15: Labeled | I15: =HYPERLINK("https://drive.google.com/file/d/1Q7Wnzi5nPYZxjBQw_UVV66coNOw_Q103/view","Open in Drive") -> Open in Drive
A16: Bird 17.wav | B16: June 18 | C16: 2022-06-18 | D16: 11:13:08 | E16: (blank) | F16: Frog (unidentified) | G16: Log note: 'Frog' — not a bird | H16: Non-bird | I16: =HYPERLINK("https://drive.google.com/file/d/1QjoOyggvPph1RYP9LO2EZnQErt6maAWX/view","Open in Drive") -> Open in Drive
A17: Bird 18.wav | B17: June 18 | C17: 2022-06-18 | D17: 11:13:11 | E17: White breasted wood wren | F17: White-breasted Wood-Wren | H17: Labeled | I17: =HYPERLINK("https://drive.google.com/file/d/1OXZFPhXO1LgFl3th7S50pZVXMDHBMPTw/view","Open in Drive") -> Open in Drive
A18: Bird 19.wav | B18: June 18 | C18: 2022-06-18 | D18: 11:13:17 | E18: Yellow-throated toucan / great tinamou | F18: Yellow-throated Toucan; Great Tinamou | G18: Uncertain — 'Very busy, multiple species?' | H18: Labeled | I18: =HYPERLINK("https://drive.google.com/file/d/1OY-WA3n0_QCTuOpvgbACXfN0KXTtswxq/view","Open in Drive") -> Open in Drive
A19: Bird 20.wav | B19: June 18 | C19: 2022-06-18 | D19: 11:14:32 | E19: White breasted wood wren | F19: White-breasted Wood-Wren | H19: Labeled | I19: =HYPERLINK("https://drive.google.com/file/d/1R5BJDlpF1thNjqQgqqBeEDpiMgxUGm6v/view","Open in Drive") -> Open in Drive
A20: Bird 21.wav | B20: June 18 | C20: 2022-06-18 | D20: 11:15:00 | E20: Yellow-throated toucan | F20: Yellow-throated Toucan | H20: Labeled | I20: =HYPERLINK("https://drive.google.com/file/d/1LcqhEZ_t2VLNPm0QelcUh-Ybnwzjia9S/view","Open in Drive") -> Open in Drive
A21: Bird 22.wav | B21: June 18 | C21: 2022-06-18 | D21: 11:16:22 | E21: Yellow-throated toucan | F21: Yellow-throated Toucan | H21: Labeled | I21: =HYPERLINK("https://drive.google.com/file/d/1NEmCYDzlcH7dpiFoRjCPwuOitRrtrBDz/view","Open in Drive") -> Open in Drive
A22: Bird 23.wav | B22: June 18 | C22: 2022-06-18 | D22: 11:16:23 | E22: White breasted wood wren | F22: White-breasted Wood-Wren | H22: Labeled | I22: =HYPERLINK("https://drive.google.com/file/d/1PhLzPtk__JKJogT9oN79sUfwx0JfjITz/view","Open in Drive") -> Open in Drive
A23: Bird 24.wav | B23: June 18 | C23: 2022-06-18 | D23: 11:17:21 | E23: (blank) | F23: Frog (Common rain frog) | G23: Log note: 'Common rain frog' — not a bird | H23: Non-bird | I23: =HYPERLINK("https://drive.google.com/file/d/1LmrehfnxZCSubakCx8HpG_Awc18BQXug/view","Open in Drive") -> Open in Drive
A24: Bird 25.wav | B24: June 18 | C24: 2022-06-18 | D24: 11:17:23 | E24: Broad-billed Motmot | F24: Broad-billed Motmot | H24: Labeled | I24: =HYPERLINK("https://drive.google.com/file/d/1R9JBAbCcuDfomerQa4jeznZIlucukwev/view","Open in Drive") -> Open in Drive
A25: Bird 26.wav | B25: June 18 | C25: 2022-06-18 | D25: 11:17:43 | E25: Mealy parrot | F25: Mealy Parrot | H25: Labeled | I25: =HYPERLINK("https://drive.google.com/file/d/1ObGDqOUup6sxeMNzDhu8nbJHMGqUlC_r/view","Open in Drive") -> Open in Drive
A26: Bird 27.wav | B26: June 18 | C26: 2022-06-18 | D26: 11:19:44 | E26: White breasted wood wren (toucan in background?) | F26: White-breasted Wood-Wren | G26: Possible Yellow-throated Toucan in background (not counted for toucan) | H26: Labeled | I26: =HYPERLINK("https://drive.google.com/file/d/1LrxnHJzhh5qmOYFqXtn9fI__56GlW5Xt/view","Open in Drive") -> Open in Drive
A27: Bird 28.wav | B27: June 18 | C27: 2022-06-18 | D27: 11:19:59 | E27: Mealy parrot | F27: Mealy Parrot | H27: Labeled | I27: =HYPERLINK("https://drive.google.com/file/d/1Ol_wa-unD9U-uJHWGHcVehBqKP3AVeRi/view","Open in Drive") -> Open in Drive
A28: Bird 29.wav | B28: June 18 | C28: 2022-06-18 | D28: 11:22:07 | E28: (blank) | F28: Insect (cicada, uncertain) | G28: Log note: 'Cicada?' — probably not a bird | H28: Non-bird | I28: =HYPERLINK("https://drive.google.com/file/d/1QPrguGf9v5ZcVYAa6datE5E7VLwba80-/view","Open in Drive") -> Open in Drive
A29: Bird 30.wav | B29: June 18 | C29: 2022-06-18 | D29: 11:22:34 | E29: Northern barred woodcreeper | F29: Northern Barred-Woodcreeper | H29: Labeled | I29: =HYPERLINK("https://drive.google.com/file/d/1O8C_t3_fUO9Lc-cPBDkr7nq4tkvbUBE6/view","Open in Drive") -> Open in Drive
A30: Bird 31.wav | B30: June 18 | C30: 2022-06-18 | D30: 11:26:16 | E30: Scarlet rumped cacique | F30: Scarlet-rumped Cacique | H30: Labeled | I30: =HYPERLINK("https://drive.google.com/file/d/1OekFxn0YyLfJ88QXhU_ZpSXyuEwBmBmd/view","Open in Drive") -> Open in Drive
A31: Bird 32.wav | B31: June 18 | C31: 2022-06-18 | D31: 11:29:58 | E31: Stripe breasted wren | F31: Stripe-breasted Wren | H31: Labeled | I31: =HYPERLINK("https://drive.google.com/file/d/1MJSD7Dg_wFW1I9ivrngTp4iqqh7l71Tx/view","Open in Drive") -> Open in Drive
A32: Bird 33.wav | B32: June 18 | C32: 2022-06-18 | D32: 11:32:11 | E32: Rufous Motmot | F32: Rufous Motmot | H32: Labeled | I32: =HYPERLINK("https://drive.google.com/file/d/1OOWY7xhMNbjtVmDrcX8NtDIz72P5eL9-/view","Open in Drive") -> Open in Drive
A33: Bird 34.wav | B33: June 18 | C33: 2022-06-18 | D33: 11:37:54 | E33: Great tinamou / red lored parrot / white breasted wood wren | F33: Great Tinamou; Red-lored Parrot; White-breasted Wood-Wren | G33: Uncertain — 'Multiple birds?' | H33: Labeled | I33: =HYPERLINK("https://drive.google.com/file/d/1QUBq0yZBayf-qcmUTpUNqbKkgwxWlQcR/view","Open in Drive") -> Open in Drive
A34: Bird 35.wav | B34: June 18 | C34: 2022-06-18 | D34: 11:38:20 | E34: Red lore parrot | F34: Red-lored Parrot | G34: Uncertain — 'Multiple birds?' | H34: Labeled | I34: =HYPERLINK("https://drive.google.com/file/d/1LyW8nNstobehi41CbZky7DBb4_F8QqEG/view","Open in Drive") -> Open in Drive
A35: Bird 36.wav | B35: June 18 | C35: 2022-06-18 | D35: 11:38:48 | E35: Lesser greenlet (vireo) | F35: Lesser Greenlet | H35: Labeled | I35: =HYPERLINK("https://drive.google.com/file/d/1MhCNjxmYrH5vqJ3vfYqC7l6w47aL8lBw/view","Open in Drive") -> Open in Drive
A36: Bird 37.wav | B36: June 18 | C36: 2022-06-18 | D36: 11:39:45 | E36: Mealy parrot | F36: Mealy Parrot | H36: Labeled | I36: =HYPERLINK("https://drive.google.com/file/d/1MMDv4CjtGOm8sMvkfMogyWiADOA3w6eA/view","Open in Drive") -> Open in Drive
A37: Bird 38.wav | B37: June 18 | C37: 2022-06-18 | D37: 11:41:55 | E37: Chestnut backed antbird | F37: Chestnut-backed Antbird | G37: Second call at 11:42:09 in same extract | H37: Labeled | I37: =HYPERLINK("https://drive.google.com/file/d/1Q3SymxnsfEBVVUt5V9N8nxZi8HdgpL-o/view","Open in Drive") -> Open in Drive
A38: Bird 39.wav | B38: June 18 | C38: 2022-06-18 | D38: 11:45:07 | E38: White breasted wood wren | F38: White-breasted Wood-Wren | H38: Labeled | I38: =HYPERLINK("https://drive.google.com/file/d/1Qv_nkcoFKxVy1IBnttHjFCPico1twY7v/view","Open in Drive") -> Open in Drive
A39: Bird 40.wav | B39: June 18 | C39: 2022-06-18 | D39: 11:55:14 | E39: White breasted wood wren | F39: White-breasted Wood-Wren | H39: Labeled | I39: =HYPERLINK("https://drive.google.com/file/d/1NP93wRtaAaKQ7bc9oz67Jlx7W5FeIdPc/view","Open in Drive") -> Open in Drive
A40: 20220601_000000_wb wren.wav | B40: June 18 | C40: 2022-06-18 | E40: wb wren (filename) | F40: White-breasted Wood-Wren | G40: Labeled via filename, not the log; source WAV named 20220601 (device clock artifact?) | H40: Labeled | I40: =HYPERLINK("https://drive.google.com/file/d/1Pdak2ABC1pdXnWuGrIDdbvrtHIb5_PYc/view","Open in Drive") -> Open in Drive
...

Sheet Splits & Clips
A1: Pre-made splits in the shared Drive folder (censused 2026-09-15)
A2: Every split file, itemized. Two Hour: 48 kHz WAV cuts covering Jun 17 12:00 → Jun 18 12:00 UTC (= Jun 17 06:00 → Jun 18 06:00 local, one full local day). One Minute: 50 FLAC clips per day for June 15–18, covering ONLY the first 50 minutes after 00:00 UTC (= 18:00–18:50 local the previous evening).
A4: File | B4: Group | C4: UTC window | D4: Local window (UTC-6) | E4: Format | F4: Drive Link
A5: Two Hour — 12 WAV files
A6: 06_17_22_1200_1400.wav | B6: Two Hour | C6: 2022-06-17 12:00–14:00 | D6: 06:00–08:00 | E6: WAV 48 kHz | F6: =HYPERLINK("https://drive.google.com/file/d/1Z43GS5sWctg2Nxn40MU8QxmbRiodLI_q/view","Open in Drive") -> Open in Drive
A7: 06_17_22_1400_1600.wav | B7: Two Hour | C7: 2022-06-17 14:00–16:00 | D7: 08:00–10:00 | E7: WAV 48 kHz | F7: =HYPERLINK("https://drive.google.com/file/d/1YxfPPSde-s_jqi0kh95x-6rvxNwP1JUP/view","Open in Drive") -> Open in Drive
A8: 06_17_22_1600_1800.wav | B8: Two Hour | C8: 2022-06-17 16:00–18:00 | D8: 10:00–12:00 | E8: WAV 48 kHz | F8: =HYPERLINK("https://drive.google.com/file/d/1Z_VVLqPhODjBPOSb2FJgSvBgIWZxGMUC/view","Open in Drive") -> Open in Drive
A9: 06_17_22_1800_2000.wav | B9: Two Hour | C9: 2022-06-17 18:00–20:00 | D9: 12:00–14:00 | E9: WAV 48 kHz | F9: =HYPERLINK("https://drive.google.com/file/d/1YvpxUzD4Dr9lRndnbL8U0JkYRgOv_o8t/view","Open in Drive") -> Open in Drive
A10: 06_17_22_2000_2200.wav | B10: Two Hour | C10: 2022-06-17 20:00–22:00 | D10: 14:00–16:00 | E10: WAV 48 kHz | F10: =HYPERLINK("https://drive.google.com/file/d/1YzScCbCE9Q_xWakkSsY-d77qHcZMaf28/view","Open in Drive") -> Open in Drive
A11: 06_17_22_2200_2400.wav | B11: Two Hour | C11: 2022-06-17 22:00–24:00 | D11: 16:00–18:00 | E11: WAV 48 kHz | F11: =HYPERLINK("https://drive.google.com/file/d/1ZcWJdWDFHWH9-LH1oKsNtajny3v88e8u/view","Open in Drive") -> Open in Drive
A12: 06_18_22_0000-0200.wav | B12: Two Hour | C12: 2022-06-18 00:00–02:00 | D12: 18:00–20:00 (prev. day) | E12: WAV 48 kHz | F12: =HYPERLINK("https://drive.google.com/file/d/1Z_p54QnHLoyigQlMBwL8XT398xJnNmqS/view","Open in Drive") -> Open in Drive
A13: 06_18_22_0200-0400.wav | B13: Two Hour | C13: 2022-06-18 02:00–04:00 | D13: 20:00–22:00 (prev. day) | E13: WAV 48 kHz | F13: =HYPERLINK("https://drive.google.com/file/d/1ZQsgIlKlVvdeXykS6TOimQwoQdKYSJrU/view","Open in Drive") -> Open in Drive
A14: 06_18_22_0400_0600.wav | B14: Two Hour | C14: 2022-06-18 04:00–06:00 | D14: 22:00–00:00 (prev. day) | E14: WAV 48 kHz | F14: =HYPERLINK("https://drive.google.com/file/d/1ZNLMI5V2YdZu_uwgC66RuSim3pyByn4G/view","Open in Drive") -> Open in Drive
A15: 06_18_22_0600_0800.wav | B15: Two Hour | C15: 2022-06-18 06:00–08:00 | D15: 00:00–02:00 | E15: WAV 48 kHz | F15: =HYPERLINK("https://drive.google.com/file/d/1Yii_RCqjhhKVtauLb4Nou9subwoHaP-D/view","Open in Drive") -> Open in Drive
A16: 06_18_22_0800_1000.wav | B16: Two Hour | C16: 2022-06-18 08:00–10:00 | D16: 02:00–04:00 | E16: WAV 48 kHz | F16: =HYPERLINK("https://drive.google.com/file/d/1YxNm4qu3YpxxOl_CZcYVjRw0tb1X0TDX/view","Open in Drive") -> Open in Drive
A17: 06_18_22_1000_1200.wav | B17: Two Hour | C17: 2022-06-18 10:00–12:00 | D17: 04:00–06:00 | E17: WAV 48 kHz | F17: =HYPERLINK("https://drive.google.com/file/d/1ZKeuha3WuQsveRwMnN-oc6FLNpU3BqTI/view","Open in Drive") -> Open in Drive
A18: One Minute — June 15 (50 clips, June 15 00:00–00:50 UTC = June 14 18:00–18:50 local)
A19: 20220615_000002_001.flac | B19: One Minute / June 15 | C19: 00:00–00:01 UTC (+2 s) | D19: 18:00–18:01 prev. day | E19: FLAC | F19: =HYPERLINK("https://drive.google.com/file/d/1IvqGdLsX0SR_JELaZsurwz64HSPASmXZ/view","Open in Drive") -> Open in Drive
A20: 20220615_000002_002.flac | B20: One Minute / June 15 | C20: 00:01–00:02 UTC (+2 s) | D20: 18:01–18:02 prev. day | E20: FLAC | F20: =HYPERLINK("https://drive.google.com/file/d/1Fj2Fh43x5e7O0M8vy-E2HF8BQv8QM7jF/view","Open in Drive") -> Open in Drive
A21: 20220615_000002_003.flac | B21: One Minute / June 15 | C21: 00:02–00:03 UTC (+2 s) | D21: 18:02–18:03 prev. day | E21: FLAC | F21: =HYPERLINK("https://drive.google.com/file/d/1TRZ33sO7ooY6gjJG3b4EIeHe78XYSKbU/view","Open in Drive") -> Open in Drive
A22: 20220615_000002_004.flac | B22: One Minute / June 15 | C22: 00:03–00:04 UTC (+2 s) | D22: 18:03–18:04 prev. day | E22: FLAC | F22: =HYPERLINK("https://drive.google.com/file/d/1YaFJQ2wQg6kafn3T5O8VN0U9v6IKQdAv/view","Open in Drive") -> Open in Drive
A23: 20220615_000002_005.flac | B23: One Minute / June 15 | C23: 00:04–00:05 UTC (+2 s) | D23: 18:04–18:05 prev. day | E23: FLAC | F23: =HYPERLINK("https://drive.google.com/file/d/1Gkg4h7lS9-6Ztq3CPvSbPBCeHZbpsJBR/view","Open in Drive") -> Open in Drive
A24: 20220615_000002_006.flac | B24: One Minute / June 15 | C24: 00:05–00:06 UTC (+2 s) | D24: 18:05–18:06 prev. day | E24: FLAC | F24: =HYPERLINK("https://drive.google.com/file/d/1HbDMX0V7tXQxjRPW7OXISgsRfc3Sfpqc/view","Open in Drive") -> Open in Drive
A25: 20220615_000002_007.flac | B25: One Minute / June 15 | C25: 00:06–00:07 UTC (+2 s) | D25: 18:06–18:07 prev. day | E25: FLAC | F25: =HYPERLINK("https://drive.google.com/file/d/1diRnFaO924lUqGOKX9K-VdFR_lRtYt8d/view","Open in Drive") -> Open in Drive
A26: 20220615_000002_008.flac | B26: One Minute / June 15 | C26: 00:07–00:08 UTC (+2 s) | D26: 18:07–18:08 prev. day | E26: FLAC | F26: =HYPERLINK("https://drive.google.com/file/d/1bO1HZwBZJOpD5W1ipM-dKcnl00FjFIe7/view","Open in Drive") -> Open in Drive
A27: 20220615_000002_009.flac | B27: One Minute / June 15 | C27: 00:08–00:09 UTC (+2 s) | D27: 18:08–18:09 prev. day | E27: FLAC | F27: =HYPERLINK("https://drive.google.com/file/d/1Uys4XowtsQxXfLmOLRyR2pnpr5xxAwj6/view","Open in Drive") -> Open in Drive
A28: 20220615_000002_010.flac | B28: One Minute / June 15 | C28: 00:09–00:10 UTC (+2 s) | D28: 18:09–18:10 prev. day | E28: FLAC | F28: =HYPERLINK("https://drive.google.com/file/d/1GijhL1yKyxGo3hBlLEq-ya5ah3fb9qyh/view","Open in Drive") -> Open in Drive
A29: 20220615_000002_011.flac | B29: One Minute / June 15 | C29: 00:10–00:11 UTC (+2 s) | D29: 18:10–18:11 prev. day | E29: FLAC | F29: =HYPERLINK("https://drive.google.com/file/d/1ptDTorWVAllbXLRGiib_jltXtF60gyok/view","Open in Drive") -> Open in Drive
A30: 20220615_000002_012.flac | B30: One Minute / June 15 | C30: 00:11–00:12 UTC (+2 s) | D30: 18:11–18:12 prev. day | E30: FLAC | F30: =HYPERLINK("https://drive.google.com/file/d/1TGqVaydL99WBLkVH-wLDvScPUS6JoNeA/view","Open in Drive") -> Open in Drive
A31: 20220615_000002_013.flac | B31: One Minute / June 15 | C31: 00:12–00:13 UTC (+2 s) | D31: 18:12–18:13 prev. day | E31: FLAC | F31: =HYPERLINK("https://drive.google.com/file/d/1QrmQ3CLeZLylOteJv0h_P2ExEXha2S58/view","Open in Drive") -> Open in Drive
A32: 20220615_000002_014.flac | B32: One Minute / June 15 | C32: 00:13–00:14 UTC (+2 s) | D32: 18:13–18:14 prev. day | E32: FLAC | F32: =HYPERLINK("https://drive.google.com/file/d/16T4qXw9KYFqtjVLGJz2PaGb8Tap2nzYs/view","Open in Drive") -> Open in Drive
A33: 20220615_000002_015.flac | B33: One Minute / June 15 | C33: 00:14–00:15 UTC (+2 s) | D33: 18:14–18:15 prev. day | E33: FLAC | F33: =HYPERLINK("https://drive.google.com/file/d/12Qt3k-3G5vRkzy3LCQ4Y6KCnOsW1q5dh/view","Open in Drive") -> Open in Drive
A34: 20220615_000002_016.flac | B34: One Minute / June 15 | C34: 00:15–00:16 UTC (+2 s) | D34: 18:15–18:16 prev. day | E34: FLAC | F34: =HYPERLINK("https://drive.google.com/file/d/1Rava7D4UnHr2csMsjRT7_I5i_sGoh30I/view","Open in Drive") -> Open in Drive
A35: 20220615_000002_017.flac | B35: One Minute / June 15 | C35: 00:16–00:17 UTC (+2 s) | D35: 18:16–18:17 prev. day | E35: FLAC | F35: =HYPERLINK("https://drive.google.com/file/d/1PPa5nr97BcZlYnp6W50EpDrx4-yn7m2g/view","Open in Drive") -> Open in Drive
A36: 20220615_000002_018.flac | B36: One Minute / June 15 | C36: 00:17–00:18 UTC (+2 s) | D36: 18:17–18:18 prev. day | E36: FLAC | F36: =HYPERLINK("https://drive.google.com/file/d/1Mn9hQ63TeDN1QKeq8a1NtUjBSIWn2To8/view","Open in Drive") -> Open in Drive
A37: 20220615_000002_019.flac | B37: One Minute / June 15 | C37: 00:18–00:19 UTC (+2 s) | D37: 18:18–18:19 prev. day | E37: FLAC | F37: =HYPERLINK("https://drive.google.com/file/d/1_zypMx3kHrbhEc2tLwkj5H_Pl4bASvV_/view","Open in Drive") -> Open in Drive
A38: 20220615_000002_020.flac | B38: One Minute / June 15 | C38: 00:19–00:20 UTC (+2 s) | D38: 18:19–18:20 prev. day | E38: FLAC | F38: =HYPERLINK("https://drive.google.com/file/d/1onK5KirDG1rA9F_zzr90w7F7bX5fMXPH/view","Open in Drive") -> Open in Drive
A39: 20220615_000002_021.flac | B39: One Minute / June 15 | C39: 00:20–00:21 UTC (+2 s) | D39: 18:20–18:21 prev. day | E39: FLAC | F39: =HYPERLINK("https://drive.google.com/file/d/1H_EbB9jJNB1Jzjy_XDdpL-ZW-IVLNjWI/view","Open in Drive") -> Open in Drive
A40: 20220615_000002_022.flac | B40: One Minute / June 15 | C40: 00:21–00:22 UTC (+2 s) | D40: 18:21–18:22 prev. day | E40: FLAC | F40: =HYPERLINK("https://drive.google.com/file/d/1KCn8p_juLVKtXoA0ilYaTjukGOsFTTfD/view","Open in Drive") -> Open in Drive
A41: 20220615_000002_023.flac | B41: One Minute / June 15 | C41: 00:22–00:23 UTC (+2 s) | D41: 18:22–18:23 prev. day | E41: FLAC | F41: =HYPERLINK("https://drive.google.com/file/d/1TCRFHiRVd3-xPYy2BbFia8JxcELP5mc0/view","Open in Drive") -> Open in Drive
...

Sheet Raw Audio
A1: Raw continuous recordings (the source of everything else)
A3: File | B3: Recording start (UTC, from filename) | C3: Drive Link
A4: 20220611_211116.WAV | B4: 2022-06-11 21:11:16 | C4: =HYPERLINK("https://drive.google.com/file/d/1RRgCDwHT00J9JYF2xopeHhZWzudQOX8H/view","Open in Drive") -> Open in Drive
A5: 20220612_000000.WAV | B5: 2022-06-12 00:00:00 | C5: =HYPERLINK("https://drive.google.com/file/d/1KfWpHaBlWv38IfIw5H4Ir7VHSWntqpeR/view","Open in Drive") -> Open in Drive
A6: 20220612_122541.WAV | B6: 2022-06-12 12:25:41 | C6: =HYPERLINK("https://drive.google.com/file/d/1Rm8U6gEectcHvsvxWPbSSKlUk8X2KO14/view","Open in Drive") -> Open in Drive
A7: 20220612_141537.WAV | B7: 2022-06-12 14:15:37 | C7: =HYPERLINK("https://drive.google.com/file/d/1RCf2ymgeRhy0Vdjo-vTvahFdKFFuwCxN/view","Open in Drive") -> Open in Drive
A8: 20220613_000002.WAV | B8: 2022-06-13 00:00:02 | C8: =HYPERLINK("https://drive.google.com/file/d/1RpVohSAnLNW27EasBVv5kVlyB6CaRjX2/view","Open in Drive") -> Open in Drive
A9: 20220613_122543.WAV | B9: 2022-06-13 12:25:43 | C9: =HYPERLINK("https://drive.google.com/file/d/1Rjox0Z-LLqn-pBiTNmhX6FBJ-FnU7s2O/view","Open in Drive") -> Open in Drive
A10: 20220614_113846.WAV | B10: 2022-06-14 11:38:46 | C10: =HYPERLINK("https://drive.google.com/file/d/1RkFfEDPaWO7d2U-7u9uE39KZ6ordtVUH/view","Open in Drive") -> Open in Drive
A11: 20220615_000002.WAV | B11: 2022-06-15 00:00:02 | C11: =HYPERLINK("https://drive.google.com/file/d/1RQxEfpAFMqec6BENMlBi6Xins2nbNVg7/view","Open in Drive") -> Open in Drive
A12: 20220615_122543.WAV | B12: 2022-06-15 12:25:43 | C12: =HYPERLINK("https://drive.google.com/file/d/1RrrVSisqqXqpbx-mdt9ZZjo3SzJGtJKi/view","Open in Drive") -> Open in Drive
A13: 20220616_000002.WAV | B13: 2022-06-16 00:00:02 | C13: =HYPERLINK("https://drive.google.com/file/d/1SGtIObWdymKx2Vi0tKaYbkpg24JGn4vR/view","Open in Drive") -> Open in Drive
A14: 20220616_122543.WAV | B14: 2022-06-16 12:25:43 | C14: =HYPERLINK("https://drive.google.com/file/d/1R_FvOAl9AGmlGmn_J8WeyOAxVrR9OCsz/view","Open in Drive") -> Open in Drive
A15: 20220617_000002.WAV | B15: 2022-06-17 00:00:02 | C15: =HYPERLINK("https://drive.google.com/file/d/1RiNPTEAAZcmKWLsU99gns-TH7cJu5v6d/view","Open in Drive") -> Open in Drive
A16: 20220617_122543.WAV | B16: 2022-06-17 12:25:43 | C16: =HYPERLINK("https://drive.google.com/file/d/1RnxQXyUI0bm7MryQOZk35nkGn59whh7Z/view","Open in Drive") -> Open in Drive
A17: 20220618_000002.WAV | B17: 2022-06-18 00:00:02 | C17: =HYPERLINK("https://drive.google.com/file/d/1RW_UI625BojNcSMXs1hKFh13cm6vqXew/view","Open in Drive") -> Open in Drive
A18: 20220618_122543.WAV | B18: 2022-06-18 12:25:43 | C18: =HYPERLINK("https://drive.google.com/file/d/1Qdy48k7zcMryZo4HSYJvTIk0-fzR-jCa/view","Open in Drive") -> Open in Drive
A20: Related folders & files
A21: AudioMoth CONFIG.TXT (48 kHz, continuous 00:00-24:00 UTC) | C21: =HYPERLINK("https://drive.google.com/file/d/1Rr0SQA92X6CsYy8vH61uUKopg1uKGCo5/view","Open in Drive") -> Open in Drive
A22: Splits / Two Hour (12 files — itemized on Splits & Clips sheet) | C22: =HYPERLINK("https://drive.google.com/drive/folders/1SOhgyZeOU0VfK3NwKPi4AWBuX1JKQ5Ya","Open in Drive") -> Open in Drive
A23: Splits / One Minute (4 × 50 clips — itemized on Splits & Clips sheet) | C23: =HYPERLINK("https://drive.google.com/drive/folders/1Rhnvan1qacjLfHGzfOipMOTQnVoUcXMl","Open in Drive") -> Open in Drive
A24: Species Song Extracts / June 17 (11 WAV + 6 .pkf) | C24: =HYPERLINK("https://drive.google.com/drive/folders/1Rj_qCbavX1OSLhKNA30LKvXXGu8fzo5E","Open in Drive") -> Open in Drive
A25: Species Song Extracts / June 18 (54 WAV + 39 .pkf) | C25: =HYPERLINK("https://drive.google.com/drive/folders/1RjVAd0fE8bEpYqEnfKpKC4c774m1rrMq","Open in Drive") -> Open in Drive
A26: Bird Extracts_M4.xlsx (annotation log: June 18 + June 17 evening block) | C26: =HYPERLINK("https://drive.google.com/file/d/1RIETKnniB_dIvH3T_pes1-d7_JkWbLp9/view","Open in Drive") -> Open in Drive
A27: wb wren source snippet 20220601_000000.wav (the two wb wren cuts were made from it) | C27: =HYPERLINK("https://drive.google.com/file/d/1MABNCuJSs0lgzW_lfYfnombw-FVS4hex/view","Open in Drive") -> Open in Drive
A29: Project files (hub folder — not audio data)
A30: Project hub folder 'Acoustic Bird Species Identification' | C30: =HYPERLINK("https://drive.google.com/drive/folders/1LmuECDC4NHF6rz51Pg-YWdomMfgMCBVF","Open in Drive") -> Open in Drive
A31: problem statement (Google Doc) | C31: =HYPERLINK("https://docs.google.com/document/d/1-8LlHOmHCU-kSUsMxnjxvXeZnZTsYObpMmgGl_qeJvI/edit","Open") -> Open
A32: Relevant Links (Google Doc) | C32: =HYPERLINK("https://docs.google.com/document/d/1xhY5mZbV2wYJcEMjh5qyuElizhsm39ChSJJRPZILWFw/edit","Open") -> Open
A33: Contact Info (Google Sheet) | C33: =HYPERLINK("https://docs.google.com/spreadsheets/d/1p2hQO51IKzAnFUxkebVzu8BFrtYpO294ANoYIA-3qcg/edit","Open") -> Open
A34: Project Description (image) | C34: =HYPERLINK("https://drive.google.com/file/d/17fVvwe2Gq4dqcN8_5k0zTQAAeG1MeI-t/view","Open") -> Open

Sheet About
A1: Costa Rica Site Data Summary — About this workbook
A3: Purpose: inventory of the team's OWN recordings from the Costa Rica AudioMoth deployment at La Selva Biological Station, before adding Xeno-canto or other public data.
A4: Source: Drive folder '2022-Jume-18_RegularMoth4_forest'; labels from 'Bird Extracts_M4.xlsx' (one sheet named 'June 18' holding the June 18 events, 00:01-11:58 UTC, followed by a June 17 evening block, 22:05-23:25 UTC). Full Drive census re-run 2026-09-15 by Claude.
A6: Coverage — what this workbook accounts for (every file in the shared Drive):
A7: - Species Summary + All Recordings: all 64 extract WAVs (44 labeled bird, 20 non-bird; zero unlabeled).
A8: - Splits & Clips: all 12 two-hour WAVs and all 200 one-minute FLAC clips (50 per day, June 15-18 — only the first 50 minutes after 00:00 UTC of each day, i.e. 18:00-18:50 local the previous evening).
A9: - Raw Audio: the 15 continuous WAVs, CONFIG.TXT, the wb-wren source snippet, the annotation log, and the project hub files (problem statement, links, contacts, image).
A10: - Excluded from itemization: 45 Adobe Audition .pkf peak files (6 in June 17, 39 in June 18) — display metadata, not audio; counts shown on Raw Audio sheet.
A12: How counts work (Species Summary, '# Recordings' column):
A13: - Counted with COUNTIF over the 'Species (canonical)' column on the All Recordings sheet, so counts update automatically if rows are edited there.
A14: - A recording with two species labels (e.g. Bird 15: macaw + wood-wren) counts once for EACH species.
A15: - Uncertain labels from the log ('Multiple birds?', 'Maybe oropendola?') are counted but flagged.
... A26: Sheets: 'Species Summary' (per-species counts + links), 'All Recordings' (one row per extract WAV), 'Splits & Clips' (every pre-cut chunk), 'Raw Audio' (source WAVs + related + project files). Machine-readable mirrors: manifests/drive_extracts.csv, drive_raw_audio.csv, drive_splits.csv.
