Workbook

Sheet Overview
A1: Total data summary: La Selva bird classifier
A2: Every recording the team holds, in one place: the 2022 AudioMoth site data, the Macaulay Library La Selva set and Xeno-canto set 2146. Made for model training and evaluation. ECE 534, Acoustic Bird Species Identification.
A3: Built 2026-10-01 from the laselva_v1 package (data-prep commit 3fe8b38), species_data_summary.xlsx and open_source_species_summary.xlsx. Counts are formulas over the Clips tab, so they follow any edit there.
A5: Parameters
A6: Blue cells are inputs. Formulas on the other tabs read them.
A7: Window length (s) | B7: 5 | C7: Perch 2.0 input length
A8: Max windows per clip | B8: 120 | C8: Cap used by examples/embed_perch.py (10 minutes)
A9: Priority-gap threshold | B9: 0.05 | C9: A species with no audio is a priority gap at or above this checklist share
A10: eBird checklists at La Selva | B10: 33576 | C10: Source: species/la_selva_ebird.csv, EBD_relJul-2026
A12: Project goal
A13: Turn raw rainforest audio from La Selva into a time-stamped record of which bird species were present: find the windows with bird calls, rank the likely species, and flag calls that match no known species.
A14: Plan: frozen Perch 2.0 embeddings (5 s windows at 32 kHz) with a small site-specific head trained on the clips listed here.
A16: Which species to train on
A17: The class set is not decided yet. This sheet lists every species we hold audio for. That does not mean the model needs a class for each one.
A18: Target species are the birds in the professor's site extracts (Target species column on the Species tab). They are the only species we can check against real site audio.
A19: The extracts were cut from about three hours of a recording that runs over 150 hours. eBird lists several hundred species at La Selva (eBird List tab). The recorder will pick up many birds that are not targets.
A20: The other species are here for two reasons. They teach the model what the targets are not. And they let it flag a call as unknown. A model that knows only the targets will label every other bird as one of them.
A21: Target species | B21: =COUNTIF(Species!$G:$G,"yes") -> 16 | C21: Bird species in the site extracts. One label is uncertain (Chestnut-headed Oropendola).
A22: Target species with train data | B22: =COUNTIFS(Species!$G:$G,"yes",Species!$P:$P,">0") -> 15 | C22: Great Green Macaw has none.
A23: Test clips of target species | B23: =SUMIFS(Species!$R:$R,Species!$G:$G,"yes") -> 94 | C23: Score every setup on these clips.
A25: Setup | B25: Classes trained | C25: Target species with own class | D25: Other bird species used | E25: Train clips | F25: How it works
A26: 1. Targets + other | B26: =COUNTIFS(Species!$G:$G,"yes",Species!$P:$P,">0")+COUNTIFS(Species!$E:$E,"nonbird",Species!$P:$P,">0")+IF(COUNTIF(Species!$Y:$Y,"other bird")>0,1,0) -> 21 | C26: =COUNTIFS(Species!$G:$G,"yes",Species!$P:$P,">0") -> 15 | D26: =COUNTIF(Species!$Y:$Y,"other bird") -> 192 | E26: =SUM(Species!$P:$P) -> 2229 | F26: Each target species is a class. All other birds go into one class, other bird. Non-bird groups stay as they are. Most focused. It cannot name a non-target species.
A27: 2. Core only | B27: =COUNTIFS(Species!$F:$F,"core",Species!$P:$P,">0") -> 93 | C27: =COUNTIFS(Species!$G:$G,"yes",Species!$F:$F,"core",Species!$P:$P,">0") -> 14 | D27: =COUNTIFS(Species!$F:$F,"core",Species!$E:$E,"bird",Species!$P:$P,">0")-C27 -> 76 | E27: =SUMIFS(Species!$P:$P,Species!$F:$F,"core") -> 1788 | F27: Every species with 10 or more La Selva clips is a class. Rarer species are left out of training, including any target with fewer than 10 clips.
A28: 3. All with train data | B28: =COUNTIF(Species!$P:$P,">0") -> 212 | C28: =COUNTIFS(Species!$G:$G,"yes",Species!$P:$P,">0") -> 15 | D28: =COUNTIFS(Species!$E:$E,"bird",Species!$P:$P,">0")-C28 -> 192 | E28: =SUM(Species!$P:$P) -> 2229 | F28: Every species with a train clip is a class. This is the few-shot setup. Classes with very few clips add noise.
A29: The Species tab has one column per setup. It gives the class each species maps to. Blank means the species is left out of training in that setup.
A30: How to choose: the head trains in minutes on frozen embeddings. Train all three on the same embeddings and compare them on the test clips of the target species. Suggested start: setup 2.
A32: Tabs
A33: Species | B33: One row per class. Target species, clips by source, split sizes, train windows, class weights, and the class each species maps to in each setup.
A34: Clips | B34: One row per recording from all three sources, with split, label, QC flags and path. The training list.
A35: Splits | B35: Totals by split, tier and source. Class balance.
A36: eBird List | B36: The 509 species eBird has for La Selva, with how much audio we hold for each. Use it as the allow-list at inference. Shows the coverage gaps.
A37: Site Audio | B37: The AudioMoth recordings on Drive: raw files, two-hour and one-minute splits, extract folders.
A38: Open Issues | B38: Known problems in the data and what to do about each.
A39: Data Dictionary | B39: What every column means.
A40: Data Sources | B40: Where every table came from.
A42: Key numbers
A43: Recordings listed | B43: =COUNTA(Clips!$A:$A)-1 -> 3320 | C43: All three sources
A44: Clips in train, val or test | B44: =Splits!B5+Splits!B6+Splits!B7 -> 3154 | C44: Usable, labeled to species or non-bird group
A45: Train clips | B45: =Splits!B5 -> 2229
A46: Train hours | B46: =Splits!C5 -> 50.023954
...

Sheet Species
A1: class_id | B1: Species | C1: Scientific name | D1: eBird code | E1: Kind | F1: Tier (laselva_v1) | G1: Target species | H1: Seed species | I1: On eBird La Selva list | J1: La Selva checklist share | K1: Site extracts | L1: Macaulay clips | M1: Xeno-canto clips | N1: Total recordings | O1: Excluded by QC | P1: Train clips | Q1: Val clips | R1: Test clips | S1: Train min | T1: Val min | U1: Test min | V1: Train windows (5 s) | W1: Class weight (setup 3) | X1: Role in splits | Y1: Setup 1: targets + other | Z1: Setup 2: core only | AA1: Setup 3: all with train data | AB1: Sessions | AC1: Recordists | AD1: Mean Macaulay rating | AE1: Multi-label clips | AF1: Short clips (<5 s) | AG1: Notes
A2: 217 | B2: White-breasted Wood-Wren | C2: Henicorhina leucosticta | D2: wbwwre1 | E2: bird | F2: core | G2: =IF(AND($E2="bird",$K2>0),"yes","") -> yes | H2: yes | I2: =IF($E2="bird",IF(COUNTIF('eBird List'!$A:$A,$B2)>0,"yes","no"),"") -> yes | J2: =IF(COUNTIF('eBird List'!$A:$A,$B2)=0,"",INDEX('eBird List'!$C:$C,MATCH($B2,'eBird List'!$A:$A,0))) -> 0.30250774 | K2: =COUNTIFS(Clips!$B:$B,"site",Clips!$F:$F,$B2)+COUNTIFS(Clips!$B:$B,"site",Clips!$O:$O,"*"&$B2&"*") -> 17 | L2: =COUNTIFS(Clips!$F:$F,$B2,Clips!$B:$B,"macaulay") -> 117 | M2: =COUNTIFS(Clips!$F:$F,$B2,Clips!$B:$B,"xeno-canto") -> 0 | N2: =K2+L2+M2 -> 134 | O2: =COUNTIFS(Clips!$F:$F,$B2,Clips!$C:$C,"excluded") -> 0 | P2: =COUNTIFS(Clips!$F:$F,$B2,Clips!$C:$C,"train") -> 81 | Q2: =COUNTIFS(Clips!$F:$F,$B2,Clips!$C:$C,"val") -> 18 | R2: =COUNTIFS(Clips!$F:$F,$B2,Clips!$C:$C,"test") -> 18 | S2: =SUMIFS(Clips!$I:$I,Clips!$F:$F,$B2,Clips!$C:$C,"train")/60 -> 92.189567 | T2: =SUMIFS(Clips!$I:$I,Clips!$F:$F,$B2,Clips!$C:$C,"val")/60 -> 17.325133 | U2: =SUMIFS(Clips!$I:$I,Clips!$F:$F,$B2,Clips!$C:$C,"test")/60 -> 7.9554167 | V2: =SUMIFS(Clips!$J:$J,Clips!$F:$F,$B2,Clips!$C:$C,"train") -> 1148 | W2: =IF(V2=0,"",Splits!$B$49/(Splits!$B$50*V2)) -> 0.13573647 | X2: =IF(P2>0,IF(AND(Q2>0,R2>0),"train + val + test",IF(R2>0,"train + test","train only")),IF(R2>0,"test only (unknown class)",IF(K2>0,"site extract only","no usable audio"))) -> train + val + test | Y2: =IF($P2=0,"",IF($E2="nonbird",$B2,IF($G2="yes",$B2,"other bird"))) -> White-breasted Wood-Wren | Z2: =IF(AND($F2="core",$P2>0),$B2,"") -> White-breasted Wood-Wren | AA2: =IF($P2>0,$B2,"") -> White-breasted Wood-Wren | AB2: 87 | AC2: 48 | AD2: =IF(COUNTIFS(Clips!$F:$F,$B2,Clips!$M:$M,">0",Clips!$C:$C,"<>excluded")=0,"",AVERAGEIFS(Clips!$M:$M,Clips!$F:$F,$B2,Clips!$M:$M,">0",Clips!$C:$C,"<>excluded")) -> 3.624359 | AE2: =COUNTIFS(Clips!$F:$F,$B2,Clips!$O:$O,"<>",Clips!$B:$B,"<>site",Clips!$C:$C,"<>excluded") -> 7 | AF2: =COUNTIFS(Clips!$F:$F,$B2,Clips!$I:$I,"<5",Clips!$C:$C,"<>excluded") -> 1 | AG2: Site: Best-covered site species, both days; one duplicate pair (Bird 12/13), one partial, two cuts labeled by filename
A3: 245 | B3: Yellow-throated Toucan | C3: Ramphastos ambiguus | D3: bkmtou1 | E3: bird | F3: core | G3: =IF(AND($E3="bird",$K3>0),"yes","") -> yes | H3: yes | I3: =IF($E3="bird",IF(COUNTIF('eBird List'!$A:$A,$B3)>0,"yes","no"),"") -> yes | J3: =IF(COUNTIF('eBird List'!$A:$A,$B3)=0,"",INDEX('eBird List'!$C:$C,MATCH($B3,'eBird List'!$A:$A,0))) -> 0.51903145 | K3: =COUNTIFS(Clips!$B:$B,"site",Clips!$F:$F,$B3)+COUNTIFS(Clips!$B:$B,"site",Clips!$O:$O,"*"&$B3&"*") -> 4 | L3: =COUNTIFS(Clips!$F:$F,$B3,Clips!$B:$B,"macaulay") -> 78 | M3: =COUNTIFS(Clips!$F:$F,$B3,Clips!$B:$B,"xeno-canto") -> 1 | N3: =K3+L3+M3 -> 83 | O3: =COUNTIFS(Clips!$F:$F,$B3,Clips!$C:$C,"excluded") -> 0 | P3: =COUNTIFS(Clips!$F:$F,$B3,Clips!$C:$C,"train") -> 55 | Q3: =COUNTIFS(Clips!$F:$F,$B3,Clips!$C:$C,"val") -> 12 | R3: =COUNTIFS(Clips!$F:$F,$B3,Clips!$C:$C,"test") -> 12 | S3: =SUMIFS(Clips!$I:$I,Clips!$F:$F,$B3,Clips!$C:$C,"train")/60 -> 51.747217 | T3: =SUMIFS(Clips!$I:$I,Clips!$F:$F,$B3,Clips!$C:$C,"val")/60 -> 12.9454 | U3: =SUMIFS(Clips!$I:$I,Clips!$F:$F,$B3,Clips!$C:$C,"test")/60 -> 16.370117 | V3: =SUMIFS(Clips!$J:$J,Clips!$F:$F,$B3,Clips!$C:$C,"train") -> 649 | W3: =IF(V3=0,"",Splits!$B$49/(Splits!$B$50*V3)) -> 0.24010088 | X3: =IF(P3>0,IF(AND(Q3>0,R3>0),"train + val + test",IF(R3>0,"train + test","train only")),IF(R3>0,"test only (unknown class)",IF(K3>0,"site extract only","no usable audio"))) -> train + val + test | Y3: =IF($P3=0,"",IF($E3="nonbird",$B3,IF($G3="yes",$B3,"other bird"))) -> Yellow-throated Toucan | Z3: =IF(AND($F3="core",$P3>0),$B3,"") -> Yellow-throated Toucan | AA3: =IF($P3>0,$B3,"") -> Yellow-throated Toucan | AB3: 62 | AC3: 47 | AD3: =IF(COUNTIFS(Clips!$F:$F,$B3,Clips!$M:$M,">0",Clips!$C:$C,"<>excluded")=0,"",AVERAGEIFS(Clips!$M:$M,Clips!$F:$F,$B3,Clips!$M:$M,">0",Clips!$C:$C,"<>excluded")) -> 3.4165909 | AE3: =COUNTIFS(Clips!$F:$F,$B3,Clips!$O:$O,"<>",Clips!$B:$B,"<>site",Clips!$C:$C,"<>excluded") -> 5 | AF3: =COUNTIFS(Clips!$F:$F,$B3,Clips!$I:$I,"<5",Clips!$C:$C,"<>excluded") -> 2 | AG3: Site: One uncertain (Bird 19, mixed with tinamou)
A4: 104 | B4: Great Tinamou | C4: Tinamus major | D4: gretin1 | E4: bird | F4: core | G4: =IF(AND($E4="bird",$K4>0),"yes","") -> yes | H4: yes | I4: =IF($E4="bird",IF(COUNTIF('eBird List'!$A:$A,$B4)>0,"yes","no"),"") -> yes | J4: =IF(COUNTIF('eBird List'!$A:$A,$B4)=0,"",INDEX('eBird List'!$C:$C,MATCH($B4,'eBird List'!$A:$A,0))) -> 0.31224684 | K4: =COUNTIFS(Clips!$B:$B,"site",Clips!$F:$F,$B4)+COUNTIFS(Clips!$B:$B,"site",Clips!$O:$O,"*"&$B4&"*") -> 4 | L4: =COUNTIFS(Clips!$F:$F,$B4,Clips!$B:$B,"macaulay") -> 63 | M4: =COUNTIFS(Clips!$F:$F,$B4,Clips!$B:$B,"xeno-canto") -> 0 | N4: =K4+L4+M4 -> 67 | O4: =COUNTIFS(Clips!$F:$F,$B4,Clips!$C:$C,"excluded") -> 1 | P4: =COUNTIFS(Clips!$F:$F,$B4,Clips!$C:$C,"train") -> 44 | Q4: =COUNTIFS(Clips!$F:$F,$B4,Clips!$C:$C,"val") -> 9 | R4: =COUNTIFS(Clips!$F:$F,$B4,Clips!$C:$C,"test") -> 9 | S4: =SUMIFS(Clips!$I:$I,Clips!$F:$F,$B4,Clips!$C:$C,"train")/60 -> 55.60075 | T4: =SUMIFS(Clips!$I:$I,Clips!$F:$F,$B4,Clips!$C:$C,"val")/60 -> 1.8543167 | U4: =SUMIFS(Clips!$I:$I,Clips!$F:$F,$B4,Clips!$C:$C,"test")/60 -> 3.3939667 | V4: =SUMIFS(Clips!$J:$J,Clips!$F:$F,$B4,Clips!$C:$C,"train") -> 594 | W4: =IF(V4=0,"",Splits!$B$49/(Splits!$B$50*V4)) -> 0.26233244 | X4: =IF(P4>0,IF(AND(Q4>0,R4>0),"train + val + test",IF(R4>0,"train + test","train only")),IF(R4>0,"test only (unknown class)",IF(K4>0,"site extract only","no usable audio"))) -> train + val + test | Y4: =IF($P4=0,"",IF($E4="nonbird",$B4,IF($G4="yes",$B4,"other bird"))) -> Great Tinamou | Z4: =IF(AND($F4="core",$P4>0),$B4,"") -> Great Tinamou | AA4: =IF($P4>0,$B4,"") -> Great Tinamou | AB4: 50 | AC4: 39 | AD4: =IF(COUNTIFS(Clips!$F:$F,$B4,Clips!$M:$M,">0",Clips!$C:$C,"<>excluded")=0,"",AVERAGEIFS(Clips!$M:$M,Clips!$F:$F,$B4,Clips!$M:$M,">0",Clips!$C:$C,"<>excluded")) -> 2.8761538 | AE4: =COUNTIFS(Clips!$F:$F,$B4,Clips!$O:$O,"<>",Clips!$B:$B,"<>site",Clips!$C:$C,"<>excluded") -> 8 | AF4: =COUNTIFS(Clips!$F:$F,$B4,Clips!$I:$I,"<5",Clips!$C:$C,"<>excluded") -> 1 | AG4: Site: June 18 Bird 1 and June 17 Bird 6 are solos; the other two are uncertain or mixed
A5: 58 | B5: Cocoa Woodcreeper | C5: Xiphorhynchus susurrans | D5: cocwoo1 | E5: bird | F5: core | G5: =IF(AND($E5="bird",$K5>0),"yes","") | I5: =IF($E5="bird",IF(COUNTIF('eBird List'!$A:$A,$B5)>0,"yes","no"),"") -> yes | J5: =IF(COUNTIF('eBird List'!$A:$A,$B5)=0,"",INDEX('eBird List'!$C:$C,MATCH($B5,'eBird List'!$A:$A,0))) -> 0.26501072 | K5: =COUNTIFS(Clips!$B:$B,"site",Clips!$F:$F,$B5)+COUNTIFS(Clips!$B:$B,"site",Clips!$O:$O,"*"&$B5&"*") -> 0 | L5: =COUNTIFS(Clips!$F:$F,$B5,Clips!$B:$B,"macaulay") -> 61 | M5: =COUNTIFS(Clips!$F:$F,$B5,Clips!$B:$B,"xeno-canto") -> 0 | N5: =K5+L5+M5 -> 61 | O5: =COUNTIFS(Clips!$F:$F,$B5,Clips!$C:$C,"excluded") -> 2 | P5: =COUNTIFS(Clips!$F:$F,$B5,Clips!$C:$C,"train") -> 41 | Q5: =COUNTIFS(Clips!$F:$F,$B5,Clips!$C:$C,"val") -> 9 | R5: =COUNTIFS(Clips!$F:$F,$B5,Clips!$C:$C,"test") -> 9 | S5: =SUMIFS(Clips!$I:$I,Clips!$F:$F,$B5,Clips!$C:$C,"train")/60 -> 112.78393 | T5: =SUMIFS(Clips!$I:$I,Clips!$F:$F,$B5,Clips!$C:$C,"val")/60 -> 43.358117 | U5: =SUMIFS(Clips!$I:$I,Clips!$F:$F,$B5,Clips!$C:$C,"test")/60 -> 10.977583 | V5: =SUMIFS(Clips!$J:$J,Clips!$F:$F,$B5,Clips!$C:$C,"train") -> 1092 | W5: =IF(V5=0,"",Splits!$B$49/(Splits!$B$50*V5)) -> 0.14269732 | X5: =IF(P5>0,IF(AND(Q5>0,R5>0),"train + val + test",IF(R5>0,"train + test","train only")),IF(R5>0,"test only (unknown class)",IF(K5>0,"site extract only","no usable audio"))) -> train + val + test | Y5: =IF($P5=0,"",IF($E5="nonbird",$B5,IF($G5="yes",$B5,"other bird"))) -> other bird | Z5: =IF(AND($F5="core",$P5>0),$B5,"") -> Cocoa Woodcreeper | AA5: =IF($P5>0,$B5,"") -> Cocoa Woodcreeper | AB5: 48 | AC5: 31 | AD5: =IF(COUNTIFS(Clips!$F:$F,$B5,Clips!$M:$M,">0",Clips!$C:$C,"<>excluded")=0,"",AVERAGEIFS(Clips!$M:$M,Clips!$F:$F,$B5,Clips!$M:$M,">0",Clips!$C:$C,"<>excluded")) -> 3.0465116 | AE5: =COUNTIFS(Clips!$F:$F,$B5,Clips!$O:$O,"<>",Clips!$B:$B,"<>site",Clips!$C:$C,"<>excluded") -> 12 | AF5: =COUNTIFS(Clips!$F:$F,$B5,Clips!$I:$I,"<5",Clips!$C:$C,"<>excluded") -> 4
A6: 165 | B6: Rufous Motmot | C6: Baryphthengus martii | D6: rufmot1 | E6: bird | F6: core | G6: =IF(AND($E6="bird",$K6>0),"yes","") -> yes | H6: yes | I6: =IF($E6="bird",IF(COUNTIF('eBird List'!$A:$A,$B6)>0,"yes","no"),"") -> yes | J6: =IF(COUNTIF('eBird List'!$A:$A,$B6)=0,"",INDEX('eBird List'!$C:$C,MATCH($B6,'eBird List'!$A:$A,0))) -> 0.31358709 | K6: =COUNTIFS(Clips!$B:$B,"site",Clips!$F:$F,$B6)+COUNTIFS(Clips!$B:$B,"site",Clips!$O:$O,"*"&$B6&"*") -> 2 | L6: =COUNTIFS(Clips!$F:$F,$B6,Clips!$B:$B,"macaulay") -> 55 | M6: =COUNTIFS(Clips!$F:$F,$B6,Clips!$B:$B,"xeno-canto") -> 0 | N6: =K6+L6+M6 -> 57 | O6: =COUNTIFS(Clips!$F:$F,$B6,Clips!$C:$C,"excluded") -> 0 | P6: =COUNTIFS(Clips!$F:$F,$B6,Clips!$C:$C,"train") -> 39 | Q6: =COUNTIFS(Clips!$F:$F,$B6,Clips!$C:$C,"val") -> 8 | R6: =COUNTIFS(Clips!$F:$F,$B6,Clips!$C:$C,"test") -> 8 | S6: =SUMIFS(Clips!$I:$I,Clips!$F:$F,$B6,Clips!$C:$C,"train")/60 -> 57.25915 | T6: =SUMIFS(Clips!$I:$I,Clips!$F:$F,$B6,Clips!$C:$C,"val")/60 -> 18.68905 | U6: =SUMIFS(Clips!$I:$I,Clips!$F:$F,$B6,Clips!$C:$C,"test")/60 -> 15.04385 | V6: =SUMIFS(Clips!$J:$J,Clips!$F:$F,$B6,Clips!$C:$C,"train") -> 527 | W6: =IF(V6=0,"",Splits!$B$49/(Splits!$B$50*V6)) -> 0.29568401 | X6: =IF(P6>0,IF(AND(Q6>0,R6>0),"train + val + test",IF(R6>0,"train + test","train only")),IF(R6>0,"test only (unknown class)",IF(K6>0,"site extract only","no usable audio"))) -> train + val + test | Y6: =IF($P6=0,"",IF($E6="nonbird",$B6,IF($G6="yes",$B6,"other bird"))) -> Rufous Motmot | Z6: =IF(AND($F6="core",$P6>0),$B6,"") -> Rufous Motmot | AA6: =IF($P6>0,$B6,"") -> Rufous Motmot | AB6: 49 | AC6: 36 | AD6: =IF(COUNTIFS(Clips!$F:$F,$B6,Clips!$M:$M,">0",Clips!$C:$C,"<>excluded")=0,"",AVERAGEIFS(Clips!$M:$M,Clips!$F:$F,$B6,Clips!$M:$M,">0",Clips!$C:$C,"<>excluded")) -> 2.3533333 | AE6: =COUNTIFS(Clips!$F:$F,$B6,Clips!$O:$O,"<>",Clips!$B:$B,"<>site",Clips!$C:$C,"<>excluded") -> 13 | AF6: =COUNTIFS(Clips!$F:$F,$B6,Clips!$I:$I,"<5",Clips!$C:$C,"<>excluded") -> 0
A7: 50 | B7: Chestnut-backed Antbird | C7: Poliocrania exsul | D7: chbant1 | E7: bird | F7: core | G7: =IF(AND($E7="bird",$K7>0),"yes","") -> yes | H7: yes | I7: =IF($E7="bird",IF(COUNTIF('eBird List'!$A:$A,$B7)>0,"yes","no"),"") -> yes | J7: =IF(COUNTIF('eBird List'!$A:$A,$B7)=0,"",INDEX('eBird List'!$C:$C,MATCH($B7,'eBird List'!$A:$A,0))) -> 0.13363712 | K7: =COUNTIFS(Clips!$B:$B,"site",Clips!$F:$F,$B7)+COUNTIFS(Clips!$B:$B,"site",Clips!$O:$O,"*"&$B7&"*") -> 1 | L7: =COUNTIFS(Clips!$F:$F,$B7,Clips!$B:$B,"macaulay") -> 54 | M7: =COUNTIFS(Clips!$F:$F,$B7,Clips!$B:$B,"xeno-canto") -> 0 | N7: =K7+L7+M7 -> 55 | O7: =COUNTIFS(Clips!$F:$F,$B7,Clips!$C:$C,"excluded") -> 0 | P7: =COUNTIFS(Clips!$F:$F,$B7,Clips!$C:$C,"train") -> 38 | Q7: =COUNTIFS(Clips!$F:$F,$B7,Clips!$C:$C,"val") -> 8 | R7: =COUNTIFS(Clips!$F:$F,$B7,Clips!$C:$C,"test") -> 8 | S7: =SUMIFS(Clips!$I:$I,Clips!$F:$F,$B7,Clips!$C:$C,"train")/60 -> 25.414433 | T7: =SUMIFS(Clips!$I:$I,Clips!$F:$F,$B7,Clips!$C:$C,"val")/60 -> 6.4244833 | U7: =SUMIFS(Clips!$I:$I,Clips!$F:$F,$B7,Clips!$C:$C,"test")/60 -> 12.426983 | V7: =SUMIFS(Clips!$J:$J,Clips!$F:$F,$B7,Clips!$C:$C,"train") -> 322 | W7: =IF(V7=0,"",Splits!$B$49/(Splits!$B$50*V7)) -> 0.48393004 | X7: =IF(P7>0,IF(AND(Q7>0,R7>0),"train + val + test",IF(R7>0,"train + test","train only")),IF(R7>0,"test only (unknown class)",IF(K7>0,"site extract only","no usable audio"))) -> train + val + test | Y7: =IF($P7=0,"",IF($E7="nonbird",$B7,IF($G7="yes",$B7,"other bird"))) -> Chestnut-backed Antbird | Z7: =IF(AND($F7="core",$P7>0),$B7,"") -> Chestnut-backed Antbird | AA7: =IF($P7>0,$B7,"") -> Chestnut-backed Antbird | AB7: 41 | AC7: 30 | AD7: =IF(COUNTIFS(Clips!$F:$F,$B7,Clips!$M:$M,">0",Clips!$C:$C,"<>excluded")=0,"",AVERAGEIFS(Clips!$M:$M,Clips!$F:$F,$B7,Clips!$M:$M,">0",Clips!$C:$C,"<>excluded")) -> 3.7093939 | AE7: =COUNTIFS(Clips!$F:$F,$B7,Clips!$O:$O,"<>",Clips!$B:$B,"<>site",Clips!$C:$C,"<>excluded") -> 5 | AF7: =COUNTIFS(Clips!$F:$F,$B7,Clips!$I:$I,"<5",Clips!$C:$C,"<>excluded") -> 2 | AG7: Site: Extract has a second call at 11:42:09
A8: 141 | B8: Olive-backed Euphonia | C8: Euphonia gouldi | D8: olbeup1 | E8: bird | F8: core | G8: =IF(AND($E8="bird",$K8>0),"yes","") | I8: =IF($E8="bird",IF(COUNTIF('eBird List'!$A:$A,$B8)>0,"yes","no"),"") -> yes | J8: =IF(COUNTIF('eBird List'!$A:$A,$B8)=0,"",INDEX('eBird List'!$C:$C,MATCH($B8,'eBird List'!$A:$A,0))) -> 0.40719562 | K8: =COUNTIFS(Clips!$B:$B,"site",Clips!$F:$F,$B8)+COUNTIFS(Clips!$B:$B,"site",Clips!$O:$O,"*"&$B8&"*") -> 0 | L8: =COUNTIFS(Clips!$F:$F,$B8,Clips!$B:$B,"macaulay") -> 55 | M8: =COUNTIFS(Clips!$F:$F,$B8,Clips!$B:$B,"xeno-canto") -> 0 | N8: =K8+L8+M8 -> 55 | O8: =COUNTIFS(Clips!$F:$F,$B8,Clips!$C:$C,"excluded") -> 2 | P8: =COUNTIFS(Clips!$F:$F,$B8,Clips!$C:$C,"train") -> 37 | Q8: =COUNTIFS(Clips!$F:$F,$B8,Clips!$C:$C,"val") -> 8 | R8: =COUNTIFS(Clips!$F:$F,$B8,Clips!$C:$C,"test") -> 8 | S8: =SUMIFS(Clips!$I:$I,Clips!$F:$F,$B8,Clips!$C:$C,"train")/60 -> 38.9944 | T8: =SUMIFS(Clips!$I:$I,Clips!$F:$F,$B8,Clips!$C:$C,"val")/60 -> 5.6537167 | U8: =SUMIFS(Clips!$I:$I,Clips!$F:$F,$B8,Clips!$C:$C,"test")/60 -> 2.40845 | V8: =SUMIFS(Clips!$J:$J,Clips!$F:$F,$B8,Clips!$C:$C,"train") -> 489 | W8: =IF(V8=0,"",Splits!$B$49/(Splits!$B$50*V8)) -> 0.3186615 | X8: =IF(P8>0,IF(AND(Q8>0,R8>0),"train + val + test",IF(R8>0,"train + test","train only")),IF(R8>0,"test only (unknown class)",IF(K8>0,"site extract only","no usable audio"))) -> train + val + test | Y8: =IF($P8=0,"",IF($E8="nonbird",$B8,IF($G8="yes",$B8,"other bird"))) -> other bird | Z8: =IF(AND($F8="core",$P8>0),$B8,"") -> Olive-backed Euphonia | AA8: =IF($P8>0,$B8,"") -> Olive-backed Euphonia | AB8: 51 | AC8: 38 | AD8: =IF(COUNTIFS(Clips!$F:$F,$B8,Clips!$M:$M,">0",Clips!$C:$C,"<>excluded")=0,"",AVERAGEIFS(Clips!$M:$M,Clips!$F:$F,$B8,Clips!$M:$M,">0",Clips!$C:$C,"<>excluded")) -> 2.8704444 | AE8: =COUNTIFS(Clips!$F:$F,$B8,Clips!$O:$O,"<>",Clips!$B:$B,"<>site",Clips!$C:$C,"<>excluded") -> 5 | AF8: =COUNTIFS(Clips!$F:$F,$B8,Clips!$I:$I,"<5",Clips!$C:$C,"<>excluded") -> 0
A9: 10 | B9: Bay Wren | C9: Cantorchilus nigricapillus | D9: baywre1 | E9: bird | F9: core | G9: =IF(AND($E9="bird",$K9>0),"yes","") | I9: =IF($E9="bird",IF(COUNTIF('eBird List'!$A:$A,$B9)>0,"yes","no"),"") -> yes | J9: =IF(COUNTIF('eBird List'!$A:$A,$B9)=0,"",INDEX('eBird List'!$C:$C,MATCH($B9,'eBird List'!$A:$A,0))) -> 0.18682988 | K9: =COUNTIFS(Clips!$B:$B,"site",Clips!$F:$F,$B9)+COUNTIFS(Clips!$B:$B,"site",Clips!$O:$O,"*"&$B9&"*") -> 0 | L9: =COUNTIFS(Clips!$F:$F,$B9,Clips!$B:$B,"macaulay") -> 49 | M9: =COUNTIFS(Clips!$F:$F,$B9,Clips!$B:$B,"xeno-canto") -> 0 | N9: =K9+L9+M9 -> 49 | O9: =COUNTIFS(Clips!$F:$F,$B9,Clips!$C:$C,"excluded") -> 0 | P9: =COUNTIFS(Clips!$F:$F,$B9,Clips!$C:$C,"train") -> 35 | Q9: =COUNTIFS(Clips!$F:$F,$B9,Clips!$C:$C,"val") -> 7 | R9: =COUNTIFS(Clips!$F:$F,$B9,Clips!$C:$C,"test") -> 7 | S9: =SUMIFS(Clips!$I:$I,Clips!$F:$F,$B9,Clips!$C:$C,"train")/60 -> 75.400433 | T9: =SUMIFS(Clips!$I:$I,Clips!$F:$F,$B9,Clips!$C:$C,"val")/60 -> 15.530533 | U9: =SUMIFS(Clips!$I:$I,Clips!$F:$F,$B9,Clips!$C:$C,"test")/60 -> 3.0135333 | V9: =SUMIFS(Clips!$J:$J,Clips!$F:$F,$B9,Clips!$C:$C,"train") -> 771 | W9: =IF(V9=0,"",Splits!$B$49/(Splits!$B$50*V9)) -> 0.20210826 | X9: =IF(P9>0,IF(AND(Q9>0,R9>0),"train + val + test",IF(R9>0,"train + test","train only")),IF(R9>0,"test only (unknown class)",IF(K9>0,"site extract only","no usable audio"))) -> train + val + test | Y9: =IF($P9=0,"",IF($E9="nonbird",$B9,IF($G9="yes",$B9,"other bird"))) -> other bird | Z9: =IF(AND($F9="core",$P9>0),$B9,"") -> Bay Wren | AA9: =IF($P9>0,$B9,"") -> Bay Wren | AB9: 37 | AC9: 23 | AD9: =IF(COUNTIFS(Clips!$F:$F,$B9,Clips!$M:$M,">0",Clips!$C:$C,"<>excluded")=0,"",AVERAGEIFS(Clips!$M:$M,Clips!$F:$F,$B9,Clips!$M:$M,">0",Clips!$C:$C,"<>excluded")) -> 3.4777778 | AE9: =COUNTIFS(Clips!$F:$F,$B9,Clips!$O:$O,"<>",Clips!$B:$B,"<>site",Clips!$C:$C,"<>excluded") -> 4 | AF9: =COUNTIFS(Clips!$F:$F,$B9,Clips!$I:$I,"<5",Clips!$C:$C,"<>excluded") -> 3
A10: 21 | B10: Black-crowned Antshrike | C10: Thamnophilus atrinucha | D10: wesant1 | E10: bird | F10: core | G10: =IF(AND($E10="bird",$K10>0),"yes","") | I10: =IF($E10="bird",IF(COUNTIF('eBird List'!$A:$A,$B10)>0,"yes","no"),"") -> yes | J10: =IF(COUNTIF('eBird List'!$A:$A,$B10)=0,"",INDEX('eBird List'!$C:$C,MATCH($B10,'eBird List'!$A:$A,0))) -> 0.20606981 | K10: =COUNTIFS(Clips!$B:$B,"site",Clips!$F:$F,$B10)+COUNTIFS(Clips!$B:$B,"site",Clips!$O:$O,"*"&$B10&"*") -> 0 | L10: =COUNTIFS(Clips!$F:$F,$B10,Clips!$B:$B,"macaulay") -> 49 | M10: =COUNTIFS(Clips!$F:$F,$B10,Clips!$B:$B,"xeno-canto") -> 0 | N10: =K10+L10+M10 -> 49 | O10: =COUNTIFS(Clips!$F:$F,$B10,Clips!$C:$C,"excluded") -> 0 | P10: =COUNTIFS(Clips!$F:$F,$B10,Clips!$C:$C,"train") -> 35 | Q10: =COUNTIFS(Clips!$F:$F,$B10,Clips!$C:$C,"val") -> 7 | R10: =COUNTIFS(Clips!$F:$F,$B10,Clips!$C:$C,"test") -> 7 | S10: =SUMIFS(Clips!$I:$I,Clips!$F:$F,$B10,Clips!$C:$C,"train")/60 -> 15.837317 | T10: =SUMIFS(Clips!$I:$I,Clips!$F:$F,$B10,Clips!$C:$C,"val")/60 -> 9.57635 | U10: =SUMIFS(Clips!$I:$I,Clips!$F:$F,$B10,Clips!$C:$C,"test")/60 -> 3.9615167 | V10: =SUMIFS(Clips!$J:$J,Clips!$F:$F,$B10,Clips!$C:$C,"train") -> 207 | W10: =IF(V10=0,"",Splits!$B$49/(Splits!$B$50*V10)) -> 0.75278006 | X10: =IF(P10>0,IF(AND(Q10>0,R10>0),"train + val + test",IF(R10>0,"train + test","train only")),IF(R10>0,"test only (unknown class)",IF(K10>0,"site extract only","no usable audio"))) -> train + val + test | Y10: =IF($P10=0,"",IF($E10="nonbird",$B10,IF($G10="yes",$B10,"other bird"))) -> other bird | Z10: =IF(AND($F10="core",$P10>0),$B10,"") -> Black-crowned Antshrike | AA10: =IF($P10>0,$B10,"") -> Black-crowned Antshrike | AB10: 46 | AC10: 36 | AD10: =IF(COUNTIFS(Clips!$F:$F,$B10,Clips!$M:$M,">0",Clips!$C:$C,"<>excluded")=0,"",AVERAGEIFS(Clips!$M:$M,Clips!$F:$F,$B10,Clips!$M:$M,">0",Clips!$C:$C,"<>excluded")) -> 3.045 | AE10: =COUNTIFS(Clips!$F:$F,$B10,Clips!$O:$O,"<>",Clips!$B:$B,"<>site",Clips!$C:$C,"<>excluded") -> 3 | AF10: =COUNTIFS(Clips!$F:$F,$B10,Clips!$I:$I,"<5",Clips!$C:$C,"<>excluded") -> 3
A11: 29 | B11: Black-throated Wren | C11: Pheugopedius atrogularis | D11: bltwre1 | E11: bird | F11: core | G11: =IF(AND($E11="bird",$K11>0),"yes","") | I11: =IF($E11="bird",IF(COUNTIF('eBird List'!$A:$A,$B11)>0,"yes","no"),"") -> yes | J11: =IF(COUNTIF('eBird List'!$A:$A,$B11)=0,"",INDEX('eBird List'!$C:$C,MATCH($B11,'eBird List'!$A:$A,0))) -> 0.1195199 | K11: =COUNTIFS(Clips!$B:$B,"site",Clips!$F:$F,$B11)+COUNTIFS(Clips!$B:$B,"site",Clips!$O:$O,"*"&$B11&"*") -> 0 | L11: =COUNTIFS(Clips!$F:$F,$B11,Clips!$B:$B,"macaulay") -> 47 | M11: =COUNTIFS(Clips!$F:$F,$B11,Clips!$B:$B,"xeno-canto") -> 2 | N11: =K11+L11+M11 -> 49 | O11: =COUNTIFS(Clips!$F:$F,$B11,Clips!$C:$C,"excluded") -> 0 | P11: =COUNTIFS(Clips!$F:$F,$B11,Clips!$C:$C,"train") -> 35 | Q11: =COUNTIFS(Clips!$F:$F,$B11,Clips!$C:$C,"val") -> 7 | R11: =COUNTIFS(Clips!$F:$F,$B11,Clips!$C:$C,"test") -> 7 | S11: =SUMIFS(Clips!$I:$I,Clips!$F:$F,$B11,Clips!$C:$C,"train")/60 -> 60.345067 | T11: =SUMIFS(Clips!$I:$I,Clips!$F:$F,$B11,Clips!$C:$C,"val")/60 -> 21.7583 | U11: =SUMIFS(Clips!$I:$I,Clips!$F:$F,$B11,Clips!$C:$C,"test")/60 -> 7.22955 | V11: =SUMIFS(Clips!$J:$J,Clips!$F:$F,$B11,Clips!$C:$C,"train") -> 691 | W11: =IF(V11=0,"",Splits!$B$49/(Splits!$B$50*V11)) -> 0.22550719 | X11: =IF(P11>0,IF(AND(Q11>0,R11>0),"train + val + test",IF(R11>0,"train + test","train only")),IF(R11>0,"test only (unknown class)",IF(K11>0,"site extract only","no usable audio"))) -> train + val + test | Y11: =IF($P11=0,"",IF($E11="nonbird",$B11,IF($G11="yes",$B11,"other bird"))) -> other bird | Z11: =IF(AND($F11="core",$P11>0),$B11,"") -> Black-throated Wren | AA11: =IF($P11>0,$B11,"") -> Black-throated Wren | AB11: 38 | AC11: 26 | AD11: =IF(COUNTIFS(Clips!$F:$F,$B11,Clips!$M:$M,">0",Clips!$C:$C,"<>excluded")=0,"",AVERAGEIFS(Clips!$M:$M,Clips!$F:$F,$B11,Clips!$M:$M,">0",Clips!$C:$C,"<>excluded")) -> 3.0555556 | AE11: =COUNTIFS(Clips!$F:$F,$B11,Clips!$O:$O,"<>",Clips!$B:$B,"<>site",Clips!$C:$C,"<>excluded") -> 1 | AF11: =COUNTIFS(Clips!$F:$F,$B11,Clips!$I:$I,"<5",Clips!$C:$C,"<>excluded") -> 3
A12: 38 | B12: Bright-rumped Attila | C12: Attila spadiceus | D12: brratt1 | E12: bird | F12: core | G12: =IF(AND($E12="bird",$K12>0),"yes","") | I12: =IF($E12="bird",IF(COUNTIF('eBird List'!$A:$A,$B12)>0,"yes","no"),"") -> yes | J12: =IF(COUNTIF('eBird List'!$A:$A,$B12)=0,"",INDEX('eBird List'!$C:$C,MATCH($B12,'eBird List'!$A:$A,0))) -> 0.25539076 | K12: =COUNTIFS(Clips!$B:$B,"site",Clips!$F:$F,$B12)+COUNTIFS(Clips!$B:$B,"site",Clips!$O:$O,"*"&$B12&"*") -> 0 | L12: =COUNTIFS(Clips!$F:$F,$B12,Clips!$B:$B,"macaulay") -> 48 | M12: =COUNTIFS(Clips!$F:$F,$B12,Clips!$B:$B,"xeno-canto") -> 0 | N12: =K12+L12+M12 -> 48 | O12: =COUNTIFS(Clips!$F:$F,$B12,Clips!$C:$C,"excluded") -> 1 | P12: =COUNTIFS(Clips!$F:$F,$B12,Clips!$C:$C,"train") -> 33 | Q12: =COUNTIFS(Clips!$F:$F,$B12,Clips!$C:$C,"val") -> 7 | R12: =COUNTIFS(Clips!$F:$F,$B12,Clips!$C:$C,"test") -> 7 | S12: =SUMIFS(Clips!$I:$I,Clips!$F:$F,$B12,Clips!$C:$C,"train")/60 -> 30.72125 | T12: =SUMIFS(Clips!$I:$I,Clips!$F:$F,$B12,Clips!$C:$C,"val")/60 -> 4.0745 | U12: =SUMIFS(Clips!$I:$I,Clips!$F:$F,$B12,Clips!$C:$C,"test")/60 -> 7.2304167 | V12: =SUMIFS(Clips!$J:$J,Clips!$F:$F,$B12,Clips!$C:$C,"train") -> 386 | W12: =IF(V12=0,"",Splits!$B$49/(Splits!$B$50*V12)) -> 0.40369293 | X12: =IF(P12>0,IF(AND(Q12>0,R12>0),"train + val + test",IF(R12>0,"train + test","train only")),IF(R12>0,"test only (unknown class)",IF(K12>0,"site extract only","no usable audio"))) -> train + val + test | Y12: =IF($P12=0,"",IF($E12="nonbird",$B12,IF($G12="yes",$B12,"other bird"))) -> other bird | Z12: =IF(AND($F12="core",$P12>0),$B12,"") -> Bright-rumped Attila | AA12: =IF($P12>0,$B12,"") -> Bright-rumped Attila | AB12: 38 | AC12: 26 | AD12: =IF(COUNTIFS(Clips!$F:$F,$B12,Clips!$M:$M,">0",Clips!$C:$C,"<>excluded")=0,"",AVERAGEIFS(Clips!$M:$M,Clips!$F:$F,$B12,Clips!$M:$M,">0",Clips!$C:$C,"<>excluded")) -> 3.2914815 | AE12: =COUNTIFS(Clips!$F:$F,$B12,Clips!$O:$O,"<>",Clips!$B:$B,"<>site",Clips!$C:$C,"<>excluded") -> 4 | AF12: =COUNTIFS(Clips!$F:$F,$B12,Clips!$I:$I,"<5",Clips!$C:$C,"<>excluded") -> 4
A13: 39 | B13: Broad-billed Motmot | C13: Electron platyrhynchum | D13: brbmot1 | E13: bird | F13: core | G13: =IF(AND($E13="bird",$K13>0),"yes","") -> yes | H13: yes | I13: =IF($E13="bird",IF(COUNTIF('eBird List'!$A:$A,$B13)>0,"yes","no"),"") -> yes | J13: =IF(COUNTIF('eBird List'!$A:$A,$B13)=0,"",INDEX('eBird List'!$C:$C,MATCH($B13,'eBird List'!$A:$A,0))) -> 0.35540267 | K13: =COUNTIFS(Clips!$B:$B,"site",Clips!$F:$F,$B13)+COUNTIFS(Clips!$B:$B,"site",Clips!$O:$O,"*"&$B13&"*") -> 3 | L13: =COUNTIFS(Clips!$F:$F,$B13,Clips!$B:$B,"macaulay") -> 48 | M13: =COUNTIFS(Clips!$F:$F,$B13,Clips!$B:$B,"xeno-canto") -> 0 | N13: =K13+L13+M13 -> 51 | O13: =COUNTIFS(Clips!$F:$F,$B13,Clips!$C:$C,"excluded") -> 1 | P13: =COUNTIFS(Clips!$F:$F,$B13,Clips!$C:$C,"train") -> 33 | Q13: =COUNTIFS(Clips!$F:$F,$B13,Clips!$C:$C,"val") -> 7 | R13: =COUNTIFS(Clips!$F:$F,$B13,Clips!$C:$C,"test") -> 7 | S13: =SUMIFS(Clips!$I:$I,Clips!$F:$F,$B13,Clips!$C:$C,"train")/60 -> 32.270167 | T13: =SUMIFS(Clips!$I:$I,Clips!$F:$F,$B13,Clips!$C:$C,"val")/60 -> 5.1131333 | U13: =SUMIFS(Clips!$I:$I,Clips!$F:$F,$B13,Clips!$C:$C,"test")/60 -> 4.4744667 | V13: =SUMIFS(Clips!$J:$J,Clips!$F:$F,$B13,Clips!$C:$C,"train") -> 402 | W13: =IF(V13=0,"",Splits!$B$49/(Splits!$B$50*V13)) -> 0.38762555 | X13: =IF(P13>0,IF(AND(Q13>0,R13>0),"train + val + test",IF(R13>0,"train + test","train only")),IF(R13>0,"test only (unknown class)",IF(K13>0,"site extract only","no usable audio"))) -> train + val + test | Y13: =IF($P13=0,"",IF($E13="nonbird",$B13,IF($G13="yes",$B13,"other bird"))) -> Broad-billed Motmot | Z13: =IF(AND($F13="core",$P13>0),$B13,"") -> Broad-billed Motmot | AA13: =IF($P13>0,$B13,"") -> Broad-billed Motmot | AB13: 40 | AC13: 28 | AD13: =IF(COUNTIFS(Clips!$F:$F,$B13,Clips!$M:$M,">0",Clips!$C:$C,"<>excluded")=0,"",AVERAGEIFS(Clips!$M:$M,Clips!$F:$F,$B13,Clips!$M:$M,">0",Clips!$C:$C,"<>excluded")) -> 2.7008824 | AE13: =COUNTIFS(Clips!$F:$F,$B13,Clips!$O:$O,"<>",Clips!$B:$B,"<>site",Clips!$C:$C,"<>excluded") -> 6 | AF13: =COUNTIFS(Clips!$F:$F,$B13,Clips!$I:$I,"<5",Clips!$C:$C,"<>excluded") -> 1 | AG13: Site: Bird 8 overlaps an ibis call
A14: 199 | B14: Stripe-breasted Wren | C14: Cantorchilus thoracicus | D14: stbwre1 | E14: bird | F14: core | G14: =IF(AND($E14="bird",$K14>0),"yes","") -> yes | H14: yes | I14: =IF($E14="bird",IF(COUNTIF('eBird List'!$A:$A,$B14)>0,"yes","no"),"") -> yes | J14: =IF(COUNTIF('eBird List'!$A:$A,$B14)=0,"",INDEX('eBird List'!$C:$C,MATCH($B14,'eBird List'!$A:$A,0))) -> 0.20443174 | K14: =COUNTIFS(Clips!$B:$B,"site",Clips!$F:$F,$B14)+COUNTIFS(Clips!$B:$B,"site",Clips!$O:$O,"*"&$B14&"*") -> 1 | L14: =COUNTIFS(Clips!$F:$F,$B14,Clips!$B:$B,"macaulay") -> 45 | M14: =COUNTIFS(Clips!$F:$F,$B14,Clips!$B:$B,"xeno-canto") -> 2 | N14: =K14+L14+M14 -> 48 | O14: =COUNTIFS(Clips!$F:$F,$B14,Clips!$C:$C,"excluded") -> 0 | P14: =COUNTIFS(Clips!$F:$F,$B14,Clips!$C:$C,"train") -> 33 | Q14: =COUNTIFS(Clips!$F:$F,$B14,Clips!$C:$C,"val") -> 7 | R14: =COUNTIFS(Clips!$F:$F,$B14,Clips!$C:$C,"test") -> 7 | S14: =SUMIFS(Clips!$I:$I,Clips!$F:$F,$B14,Clips!$C:$C,"train")/60 -> 31.088667 | T14: =SUMIFS(Clips!$I:$I,Clips!$F:$F,$B14,Clips!$C:$C,"val")/60 -> 9.4998333 | U14: =SUMIFS(Clips!$I:$I,Clips!$F:$F,$B14,Clips!$C:$C,"test")/60 -> 13.229283 | V14: =SUMIFS(Clips!$J:$J,Clips!$F:$F,$B14,Clips!$C:$C,"train") -> 391 | W14: =IF(V14=0,"",Splits!$B$49/(Splits!$B$50*V14)) -> 0.39853062 | X14: =IF(P14>0,IF(AND(Q14>0,R14>0),"train + val + test",IF(R14>0,"train + test","train only")),IF(R14>0,"test only (unknown class)",IF(K14>0,"site extract only","no usable audio"))) -> train + val + test | Y14: =IF($P14=0,"",IF($E14="nonbird",$B14,IF($G14="yes",$B14,"other bird"))) -> Stripe-breasted Wren | Z14: =IF(AND($F14="core",$P14>0),$B14,"") -> Stripe-breasted Wren | AA14: =IF($P14>0,$B14,"") -> Stripe-breasted Wren | AB14: 35 | AC14: 23 | AD14: =IF(COUNTIFS(Clips!$F:$F,$B14,Clips!$M:$M,">0",Clips!$C:$C,"<>excluded")=0,"",AVERAGEIFS(Clips!$M:$M,Clips!$F:$F,$B14,Clips!$M:$M,">0",Clips!$C:$C,"<>excluded")) -> 3.2825 | AE14: =COUNTIFS(Clips!$F:$F,$B14,Clips!$O:$O,"<>",Clips!$B:$B,"<>site",Clips!$C:$C,"<>excluded") -> 7 | AF14: =COUNTIFS(Clips!$F:$F,$B14,Clips!$I:$I,"<5",Clips!$C:$C,"<>excluded") -> 1
A15: 160 | B15: Red-throated Ant-Tanager | C15: Driophlox fuscicauda | D15: rtatan1 | E15: bird | F15: core | G15: =IF(AND($E15="bird",$K15>0),"yes","") | I15: =IF($E15="bird",IF(COUNTIF('eBird List'!$A:$A,$B15)>0,"yes","no"),"") -> yes | J15: =IF(COUNTIF('eBird List'!$A:$A,$B15)=0,"",INDEX('eBird List'!$C:$C,MATCH($B15,'eBird List'!$A:$A,0))) -> 0.21318799 | K15: =COUNTIFS(Clips!$B:$B,"site",Clips!$F:$F,$B15)+COUNTIFS(Clips!$B:$B,"site",Clips!$O:$O,"*"&$B15&"*") -> 0 | L15: =COUNTIFS(Clips!$F:$F,$B15,Clips!$B:$B,"macaulay") -> 43 | M15: =COUNTIFS(Clips!$F:$F,$B15,Clips!$B:$B,"xeno-canto") -> 0 | N15: =K15+L15+M15 -> 43 | O15: =COUNTIFS(Clips!$F:$F,$B15,Clips!$C:$C,"excluded") -> 1 | P15: =COUNTIFS(Clips!$F:$F,$B15,Clips!$C:$C,"train") -> 30 | Q15: =COUNTIFS(Clips!$F:$F,$B15,Clips!$C:$C,"val") -> 6 | R15: =COUNTIFS(Clips!$F:$F,$B15,Clips!$C:$C,"test") -> 6 | S15: =SUMIFS(Clips!$I:$I,Clips!$F:$F,$B15,Clips!$C:$C,"train")/60 -> 21.5531 | T15: =SUMIFS(Clips!$I:$I,Clips!$F:$F,$B15,Clips!$C:$C,"val")/60 -> 12.751683 | U15: =SUMIFS(Clips!$I:$I,Clips!$F:$F,$B15,Clips!$C:$C,"test")/60 -> 3.6911667 | V15: =SUMIFS(Clips!$J:$J,Clips!$F:$F,$B15,Clips!$C:$C,"train") -> 276 | W15: =IF(V15=0,"",Splits!$B$49/(Splits!$B$50*V15)) -> 0.56458504 | X15: =IF(P15>0,IF(AND(Q15>0,R15>0),"train + val + test",IF(R15>0,"train + test","train only")),IF(R15>0,"test only (unknown class)",IF(K15>0,"site extract only","no usable audio"))) -> train + val + test | Y15: =IF($P15=0,"",IF($E15="nonbird",$B15,IF($G15="yes",$B15,"other bird"))) -> other bird | Z15: =IF(AND($F15="core",$P15>0),$B15,"") -> Red-throated Ant-Tanager | AA15: =IF($P15>0,$B15,"") -> Red-throated Ant-Tanager | AB15: 30 | AC15: 24 | AD15: =IF(COUNTIFS(Clips!$F:$F,$B15,Clips!$M:$M,">0",Clips!$C:$C,"<>excluded")=0,"",AVERAGEIFS(Clips!$M:$M,Clips!$F:$F,$B15,Clips!$M:$M,">0",Clips!$C:$C,"<>excluded")) -> 3.4666667 | AE15: =COUNTIFS(Clips!$F:$F,$B15,Clips!$O:$O,"<>",Clips!$B:$B,"<>site",Clips!$C:$C,"<>excluded") -> 4 | AF15: =COUNTIFS(Clips!$F:$F,$B15,Clips!$I:$I,"<5",Clips!$C:$C,"<>excluded") -> 3
A16: 219 | B16: White-collared Manakin | C16: Manacus candei | D16: whcman1 | E16: bird | F16: core | G16: =IF(AND($E16="bird",$K16>0),"yes","") | I16: =IF($E16="bird",IF(COUNTIF('eBird List'!$A:$A,$B16)>0,"yes","no"),"") -> yes | J16: =IF(COUNTIF('eBird List'!$A:$A,$B16)=0,"",INDEX('eBird List'!$C:$C,MATCH($B16,'eBird List'!$A:$A,0))) -> 0.35701096 | K16: =COUNTIFS(Clips!$B:$B,"site",Clips!$F:$F,$B16)+COUNTIFS(Clips!$B:$B,"site",Clips!$O:$O,"*"&$B16&"*") -> 0 | L16: =COUNTIFS(Clips!$F:$F,$B16,Clips!$B:$B,"macaulay") -> 43 | M16: =COUNTIFS(Clips!$F:$F,$B16,Clips!$B:$B,"xeno-canto") -> 0 | N16: =K16+L16+M16 -> 43 | O16: =COUNTIFS(Clips!$F:$F,$B16,Clips!$C:$C,"excluded") -> 1 | P16: =COUNTIFS(Clips!$F:$F,$B16,Clips!$C:$C,"train") -> 30 | Q16: =COUNTIFS(Clips!$F:$F,$B16,Clips!$C:$C,"val") -> 6 | R16: =COUNTIFS(Clips!$F:$F,$B16,Clips!$C:$C,"test") -> 6 | S16: =SUMIFS(Clips!$I:$I,Clips!$F:$F,$B16,Clips!$C:$C,"train")/60 -> 44.996417 | T16: =SUMIFS(Clips!$I:$I,Clips!$F:$F,$B16,Clips!$C:$C,"val")/60 -> 4.9903167 | U16: =SUMIFS(Clips!$I:$I,Clips!$F:$F,$B16,Clips!$C:$C,"test")/60 -> 3.1034833 | V16: =SUMIFS(Clips!$J:$J,Clips!$F:$F,$B16,Clips!$C:$C,"train") -> 524 | W16: =IF(V16=0,"",Splits!$B$49/(Splits!$B$50*V16)) -> 0.29737685 | X16: =IF(P16>0,IF(AND(Q16>0,R16>0),"train + val + test",IF(R16>0,"train + test","train only")),IF(R16>0,"test only (unknown class)",IF(K16>0,"site extract only","no usable audio"))) -> train + val + test | Y16: =IF($P16=0,"",IF($E16="nonbird",$B16,IF($G16="yes",$B16,"other bird"))) -> other bird | Z16: =IF(AND($F16="core",$P16>0),$B16,"") -> White-collared Manakin | AA16: =IF($P16>0,$B16,"") -> White-collared Manakin | AB16: 35 | AC16: 30 | AD16: =IF(COUNTIFS(Clips!$F:$F,$B16,Clips!$M:$M,">0",Clips!$C:$C,"<>excluded")=0,"",AVERAGEIFS(Clips!$M:$M,Clips!$F:$F,$B16,Clips!$M:$M,">0",Clips!$C:$C,"<>excluded")) -> 3.0914286 | AE16: =COUNTIFS(Clips!$F:$F,$B16,Clips!$O:$O,"<>",Clips!$B:$B,"<>site",Clips!$C:$C,"<>excluded") -> 4 | AF16: =COUNTIFS(Clips!$F:$F,$B16,Clips!$I:$I,"<5",Clips!$C:$C,"<>excluded") -> 5
A17: 187 | B17: Slaty-tailed Trogon | C17: Trogon massena | D17: slttro1 | E17: bird | F17: core | G17: =IF(AND($E17="bird",$K17>0),"yes","") | I17: =IF($E17="bird",IF(COUNTIF('eBird List'!$A:$A,$B17)>0,"yes","no"),"") -> yes | J17: =IF(COUNTIF('eBird List'!$A:$A,$B17)=0,"",INDEX('eBird List'!$C:$C,MATCH($B17,'eBird List'!$A:$A,0))) -> 0.338873 | K17: =COUNTIFS(Clips!$B:$B,"site",Clips!$F:$F,$B17)+COUNTIFS(Clips!$B:$B,"site",Clips!$O:$O,"*"&$B17&"*") -> 0 | L17: =COUNTIFS(Clips!$F:$F,$B17,Clips!$B:$B,"macaulay") -> 39 | M17: =COUNTIFS(Clips!$F:$F,$B17,Clips!$B:$B,"xeno-canto") -> 0 | N17: =K17+L17+M17 -> 39 | O17: =COUNTIFS(Clips!$F:$F,$B17,Clips!$C:$C,"excluded") -> 0 | P17: =COUNTIFS(Clips!$F:$F,$B17,Clips!$C:$C,"train") -> 27 | Q17: =COUNTIFS(Clips!$F:$F,$B17,Clips!$C:$C,"val") -> 6 | R17: =COUNTIFS(Clips!$F:$F,$B17,Clips!$C:$C,"test") -> 6 | S17: =SUMIFS(Clips!$I:$I,Clips!$F:$F,$B17,Clips!$C:$C,"train")/60 -> 19.804183 | T17: =SUMIFS(Clips!$I:$I,Clips!$F:$F,$B17,Clips!$C:$C,"val")/60 -> 4.8480667 | U17: =SUMIFS(Clips!$I:$I,Clips!$F:$F,$B17,Clips!$C:$C,"test")/60 -> 6.0718833 | V17: =SUMIFS(Clips!$J:$J,Clips!$F:$F,$B17,Clips!$C:$C,"train") -> 252 | W17: =IF(V17=0,"",Splits!$B$49/(Splits!$B$50*V17)) -> 0.61835505 | X17: =IF(P17>0,IF(AND(Q17>0,R17>0),"train + val + test",IF(R17>0,"train + test","train only")),IF(R17>0,"test only (unknown class)",IF(K17>0,"site extract only","no usable audio"))) -> train + val + test | Y17: =IF($P17=0,"",IF($E17="nonbird",$B17,IF($G17="yes",$B17,"other bird"))) -> other bird | Z17: =IF(AND($F17="core",$P17>0),$B17,"") -> Slaty-tailed Trogon | AA17: =IF($P17>0,$B17,"") -> Slaty-tailed Trogon | AB17: 35 | AC17: 25 | AD17: =IF(COUNTIFS(Clips!$F:$F,$B17,Clips!$M:$M,">0",Clips!$C:$C,"<>excluded")=0,"",AVERAGEIFS(Clips!$M:$M,Clips!$F:$F,$B17,Clips!$M:$M,">0",Clips!$C:$C,"<>excluded")) -> 2.6419355 | AE17: =COUNTIFS(Clips!$F:$F,$B17,Clips!$O:$O,"<>",Clips!$B:$B,"<>site",Clips!$C:$C,"<>excluded") -> 3 | AF17: =COUNTIFS(Clips!$F:$F,$B17,Clips!$I:$I,"<5",Clips!$C:$C,"<>excluded") -> 0
A18: 70 | B18: Crested Guan | C18: Penelope purpurascens | D18: cregua1 | E18: bird | F18: core | G18: =IF(AND($E18="bird",$K18>0),"yes","") | I18: =IF($E18="bird",IF(COUNTIF('eBird List'!$A:$A,$B18)>0,"yes","no"),"") -> yes | J18: =IF(COUNTIF('eBird List'!$A:$A,$B18)=0,"",INDEX('eBird List'!$C:$C,MATCH($B18,'eBird List'!$A:$A,0))) -> 0.38506671 | K18: =COUNTIFS(Clips!$B:$B,"site",Clips!$F:$F,$B18)+COUNTIFS(Clips!$B:$B,"site",Clips!$O:$O,"*"&$B18&"*") -> 0 | L18: =COUNTIFS(Clips!$F:$F,$B18,Clips!$B:$B,"macaulay") -> 35 | M18: =COUNTIFS(Clips!$F:$F,$B18,Clips!$B:$B,"xeno-canto") -> 1 | N18: =K18+L18+M18 -> 36 | O18: =COUNTIFS(Clips!$F:$F,$B18,Clips!$C:$C,"excluded") -> 0 | P18: =COUNTIFS(Clips!$F:$F,$B18,Clips!$C:$C,"train") -> 26 | Q18: =COUNTIFS(Clips!$F:$F,$B18,Clips!$C:$C,"val") -> 5 | R18: =COUNTIFS(Clips!$F:$F,$B18,Clips!$C:$C,"test") -> 5 | S18: =SUMIFS(Clips!$I:$I,Clips!$F:$F,$B18,Clips!$C:$C,"train")/60 -> 35.309583 | T18: =SUMIFS(Clips!$I:$I,Clips!$F:$F,$B18,Clips!$C:$C,"val")/60 -> 2.7726167 | U18: =SUMIFS(Clips!$I:$I,Clips!$F:$F,$B18,Clips!$C:$C,"test")/60 -> 3.5486667 | V18: =SUMIFS(Clips!$J:$J,Clips!$F:$F,$B18,Clips!$C:$C,"train") -> 437 | W18: =IF(V18=0,"",Splits!$B$49/(Splits!$B$50*V18)) -> 0.35658003 | X18: =IF(P18>0,IF(AND(Q18>0,R18>0),"train + val + test",IF(R18>0,"train + test","train only")),IF(R18>0,"test only (unknown class)",IF(K18>0,"site extract only","no usable audio"))) -> train + val + test | Y18: =IF($P18=0,"",IF($E18="nonbird",$B18,IF($G18="yes",$B18,"other bird"))) -> other bird | Z18: =IF(AND($F18="core",$P18>0),$B18,"") -> Crested Guan | AA18: =IF($P18>0,$B18,"") -> Crested Guan | AB18: 31 | AC18: 25 | AD18: =IF(COUNTIFS(Clips!$F:$F,$B18,Clips!$M:$M,">0",Clips!$C:$C,"<>excluded")=0,"",AVERAGEIFS(Clips!$M:$M,Clips!$F:$F,$B18,Clips!$M:$M,">0",Clips!$C:$C,"<>excluded")) -> 2.7903226 | AE18: =COUNTIFS(Clips!$F:$F,$B18,Clips!$O:$O,"<>",Clips!$B:$B,"<>site",Clips!$C:$C,"<>excluded") -> 3 | AF18: =COUNTIFS(Clips!$F:$F,$B18,Clips!$I:$I,"<5",Clips!$C:$C,"<>excluded") -> 2
A19: 44 | B19: Buff-rumped Warbler | C19: Myiothlypis fulvicauda | D19: burwar1 | E19: bird | F19: core | G19: =IF(AND($E19="bird",$K19>0),"yes","") | I19: =IF($E19="bird",IF(COUNTIF('eBird List'!$A:$A,$B19)>0,"yes","no"),"") -> yes | J19: =IF(COUNTIF('eBird List'!$A:$A,$B19)=0,"",INDEX('eBird List'!$C:$C,MATCH($B19,'eBird List'!$A:$A,0))) -> 0.19290565 | K19: =COUNTIFS(Clips!$B:$B,"site",Clips!$F:$F,$B19)+COUNTIFS(Clips!$B:$B,"site",Clips!$O:$O,"*"&$B19&"*") -> 0 | L19: =COUNTIFS(Clips!$F:$F,$B19,Clips!$B:$B,"macaulay") -> 34 | M19: =COUNTIFS(Clips!$F:$F,$B19,Clips!$B:$B,"xeno-canto") -> 1 | N19: =K19+L19+M19 -> 35 | O19: =COUNTIFS(Clips!$F:$F,$B19,Clips!$C:$C,"excluded") -> 0 | P19: =COUNTIFS(Clips!$F:$F,$B19,Clips!$C:$C,"train") -> 25 | Q19: =COUNTIFS(Clips!$F:$F,$B19,Clips!$C:$C,"val") -> 5 | R19: =COUNTIFS(Clips!$F:$F,$B19,Clips!$C:$C,"test") -> 5 | S19: =SUMIFS(Clips!$I:$I,Clips!$F:$F,$B19,Clips!$C:$C,"train")/60 -> 14.90505 | T19: =SUMIFS(Clips!$I:$I,Clips!$F:$F,$B19,Clips!$C:$C,"val")/60 -> 2.3785167 | U19: =SUMIFS(Clips!$I:$I,Clips!$F:$F,$B19,Clips!$C:$C,"test")/60 -> 3.8222333 | V19: =SUMIFS(Clips!$J:$J,Clips!$F:$F,$B19,Clips!$C:$C,"train") -> 191 | W19: =IF(V19=0,"",Splits!$B$49/(Splits!$B$50*V19)) -> 0.81584017 | X19: =IF(P19>0,IF(AND(Q19>0,R19>0),"train + val + test",IF(R19>0,"train + test","train only")),IF(R19>0,"test only (unknown class)",IF(K19>0,"site extract only","no usable audio"))) -> train + val + test | Y19: =IF($P19=0,"",IF($E19="nonbird",$B19,IF($G19="yes",$B19,"other bird"))) -> other bird | Z19: =IF(AND($F19="core",$P19>0),$B19,"") -> Buff-rumped Warbler | AA19: =IF($P19>0,$B19,"") -> Buff-rumped Warbler | AB19: 29 | AC19: 24 | AD19: =IF(COUNTIFS(Clips!$F:$F,$B19,Clips!$M:$M,">0",Clips!$C:$C,"<>excluded")=0,"",AVERAGEIFS(Clips!$M:$M,Clips!$F:$F,$B19,Clips!$M:$M,">0",Clips!$C:$C,"<>excluded")) -> 3.0588235 | AE19: =COUNTIFS(Clips!$F:$F,$B19,Clips!$O:$O,"<>",Clips!$B:$B,"<>site",Clips!$C:$C,"<>excluded") -> 1 | AF19: =COUNTIFS(Clips!$F:$F,$B19,Clips!$I:$I,"<5",Clips!$C:$C,"<>excluded") -> 1
A20: 128 | B20: Montezuma Oropendola | C20: Psarocolius montezuma | D20: monoro1 | E20: bird | F20: core | G20: =IF(AND($E20="bird",$K20>0),"yes","") | I20: =IF($E20="bird",IF(COUNTIF('eBird List'!$A:$A,$B20)>0,"yes","no"),"") -> yes | J20: =IF(COUNTIF('eBird List'!$A:$A,$B20)=0,"",INDEX('eBird List'!$C:$C,MATCH($B20,'eBird List'!$A:$A,0))) -> 0.49175006 | K20: =COUNTIFS(Clips!$B:$B,"site",Clips!$F:$F,$B20)+COUNTIFS(Clips!$B:$B,"site",Clips!$O:$O,"*"&$B20&"*") -> 0 | L20: =COUNTIFS(Clips!$F:$F,$B20,Clips!$B:$B,"macaulay") -> 33 | M20: =COUNTIFS(Clips!$F:$F,$B20,Clips!$B:$B,"xeno-canto") -> 2 | N20: =K20+L20+M20 -> 35 | O20: =COUNTIFS(Clips!$F:$F,$B20,Clips!$C:$C,"excluded") -> 0 | P20: =COUNTIFS(Clips!$F:$F,$B20,Clips!$C:$C,"train") -> 25 | Q20: =COUNTIFS(Clips!$F:$F,$B20,Clips!$C:$C,"val") -> 5 | R20: =COUNTIFS(Clips!$F:$F,$B20,Clips!$C:$C,"test") -> 5 | S20: =SUMIFS(Clips!$I:$I,Clips!$F:$F,$B20,Clips!$C:$C,"train")/60 -> 33.690733 | T20: =SUMIFS(Clips!$I:$I,Clips!$F:$F,$B20,Clips!$C:$C,"val")/60 -> 4.3963167 | U20: =SUMIFS(Clips!$I:$I,Clips!$F:$F,$B20,Clips!$C:$C,"test")/60 -> 0.85765 | V20: =SUMIFS(Clips!$J:$J,Clips!$F:$F,$B20,Clips!$C:$C,"train") -> 385 | W20: =IF(V20=0,"",Splits!$B$49/(Splits!$B$50*V20)) -> 0.40474148 | X20: =IF(P20>0,IF(AND(Q20>0,R20>0),"train + val + test",IF(R20>0,"train + test","train only")),IF(R20>0,"test only (unknown class)",IF(K20>0,"site extract only","no usable audio"))) -> train + val + test | Y20: =IF($P20=0,"",IF($E20="nonbird",$B20,IF($G20="yes",$B20,"other bird"))) -> other bird | Z20: =IF(AND($F20="core",$P20>0),$B20,"") -> Montezuma Oropendola | AA20: =IF($P20>0,$B20,"") -> Montezuma Oropendola | AB20: 29 | AC20: 20 | AD20: =IF(COUNTIFS(Clips!$F:$F,$B20,Clips!$M:$M,">0",Clips!$C:$C,"<>excluded")=0,"",AVERAGEIFS(Clips!$M:$M,Clips!$F:$F,$B20,Clips!$M:$M,">0",Clips!$C:$C,"<>excluded")) -> 2.9389655 | AE20: =COUNTIFS(Clips!$F:$F,$B20,Clips!$O:$O,"<>",Clips!$B:$B,"<>site",Clips!$C:$C,"<>excluded") -> 5 | AF20: =COUNTIFS(Clips!$F:$F,$B20,Clips!$I:$I,"<5",Clips!$C:$C,"<>excluded") -> 7
A21: 176 | B21: Scarlet-rumped Cacique | C21: Cacicus uropygialis | D21: scrcac2 | E21: bird | F21: core | G21: =IF(AND($E21="bird",$K21>0),"yes","") -> yes | H21: yes | I21: =IF($E21="bird",IF(COUNTIF('eBird List'!$A:$A,$B21)>0,"yes","no"),"") -> yes | J21: =IF(COUNTIF('eBird List'!$A:$A,$B21)=0,"",INDEX('eBird List'!$C:$C,MATCH($B21,'eBird List'!$A:$A,0))) -> 0.2023767 | K21: =COUNTIFS(Clips!$B:$B,"site",Clips!$F:$F,$B21)+COUNTIFS(Clips!$B:$B,"site",Clips!$O:$O,"*"&$B21&"*") -> 1 | L21: =COUNTIFS(Clips!$F:$F,$B21,Clips!$B:$B,"macaulay") -> 35 | M21: =COUNTIFS(Clips!$F:$F,$B21,Clips!$B:$B,"xeno-canto") -> 0 | N21: =K21+L21+M21 -> 36 | O21: =COUNTIFS(Clips!$F:$F,$B21,Clips!$C:$C,"excluded") -> 0 | P21: =COUNTIFS(Clips!$F:$F,$B21,Clips!$C:$C,"train") -> 25 | Q21: =COUNTIFS(Clips!$F:$F,$B21,Clips!$C:$C,"val") -> 5 | R21: =COUNTIFS(Clips!$F:$F,$B21,Clips!$C:$C,"test") -> 5 | S21: =SUMIFS(Clips!$I:$I,Clips!$F:$F,$B21,Clips!$C:$C,"train")/60 -> 21.744667 | T21: =SUMIFS(Clips!$I:$I,Clips!$F:$F,$B21,Clips!$C:$C,"val")/60 -> 3.75385 | U21: =SUMIFS(Clips!$I:$I,Clips!$F:$F,$B21,Clips!$C:$C,"test")/60 -> 1.7730333 | V21: =SUMIFS(Clips!$J:$J,Clips!$F:$F,$B21,Clips!$C:$C,"train") -> 275 | W21: =IF(V21=0,"",Splits!$B$49/(Splits!$B$50*V21)) -> 0.56663808 | X21: =IF(P21>0,IF(AND(Q21>0,R21>0),"train + val + test",IF(R21>0,"train + test","train only")),IF(R21>0,"test only (unknown class)",IF(K21>0,"site extract only","no usable audio"))) -> train + val + test | Y21: =IF($P21=0,"",IF($E21="nonbird",$B21,IF($G21="yes",$B21,"other bird"))) -> Scarlet-rumped Cacique | Z21: =IF(AND($F21="core",$P21>0),$B21,"") -> Scarlet-rumped Cacique | AA21: =IF($P21>0,$B21,"") -> Scarlet-rumped Cacique | AB21: 29 | AC21: 19 | AD21: =IF(COUNTIFS(Clips!$F:$F,$B21,Clips!$M:$M,">0",Clips!$C:$C,"<>excluded")=0,"",AVERAGEIFS(Clips!$M:$M,Clips!$F:$F,$B21,Clips!$M:$M,">0",Clips!$C:$C,"<>excluded")) -> 3.2640741 | AE21: =COUNTIFS(Clips!$F:$F,$B21,Clips!$O:$O,"<>",Clips!$B:$B,"<>site",Clips!$C:$C,"<>excluded") -> 7 | AF21: =COUNTIFS(Clips!$F:$F,$B21,Clips!$I:$I,"<5",Clips!$C:$C,"<>excluded") -> 2
A22: 126 | B22: Middle American Screech-Owl | C22: Megascops guatemalae | D22: vesowl | E22: bird | F22: core | G22: =IF(AND($E22="bird",$K22>0),"yes","") | I22: =IF($E22="bird",IF(COUNTIF('eBird List'!$A:$A,$B22)>0,"yes","no"),"") -> yes | J22: =IF(COUNTIF('eBird List'!$A:$A,$B22)=0,"",INDEX('eBird List'!$C:$C,MATCH($B22,'eBird List'!$A:$A,0))) -> 0.086728616 | K22: =COUNTIFS(Clips!$B:$B,"site",Clips!$F:$F,$B22)+COUNTIFS(Clips!$B:$B,"site",Clips!$O:$O,"*"&$B22&"*") -> 0 | L22: =COUNTIFS(Clips!$F:$F,$B22,Clips!$B:$B,"macaulay") -> 34 | M22: =COUNTIFS(Clips!$F:$F,$B22,Clips!$B:$B,"xeno-canto") -> 0 | N22: =K22+L22+M22 -> 34 | O22: =COUNTIFS(Clips!$F:$F,$B22,Clips!$C:$C,"excluded") -> 0 | P22: =COUNTIFS(Clips!$F:$F,$B22,Clips!$C:$C,"train") -> 24 | Q22: =COUNTIFS(Clips!$F:$F,$B22,Clips!$C:$C,"val") -> 5 | R22: =COUNTIFS(Clips!$F:$F,$B22,Clips!$C:$C,"test") -> 5 | S22: =SUMIFS(Clips!$I:$I,Clips!$F:$F,$B22,Clips!$C:$C,"train")/60 -> 63.479633 | T22: =SUMIFS(Clips!$I:$I,Clips!$F:$F,$B22,Clips!$C:$C,"val")/60 -> 0.73433333 | U22: =SUMIFS(Clips!$I:$I,Clips!$F:$F,$B22,Clips!$C:$C,"test")/60 -> 2.7118333 | V22: =SUMIFS(Clips!$J:$J,Clips!$F:$F,$B22,Clips!$C:$C,"train") -> 708 | W22: =IF(V22=0,"",Splits!$B$49/(Splits!$B$50*V22)) -> 0.22009247 | X22: =IF(P22>0,IF(AND(Q22>0,R22>0),"train + val + test",IF(R22>0,"train + test","train only")),IF(R22>0,"test only (unknown class)",IF(K22>0,"site extract only","no usable audio"))) -> train + val + test | Y22: =IF($P22=0,"",IF($E22="nonbird",$B22,IF($G22="yes",$B22,"other bird"))) -> other bird | Z22: =IF(AND($F22="core",$P22>0),$B22,"") -> Middle American Screech-Owl | AA22: =IF($P22>0,$B22,"") -> Middle American Screech-Owl | AB22: 27 | AC22: 19 | AD22: =IF(COUNTIFS(Clips!$F:$F,$B22,Clips!$M:$M,">0",Clips!$C:$C,"<>excluded")=0,"",AVERAGEIFS(Clips!$M:$M,Clips!$F:$F,$B22,Clips!$M:$M,">0",Clips!$C:$C,"<>excluded")) -> 2.50125 | AE22: =COUNTIFS(Clips!$F:$F,$B22,Clips!$O:$O,"<>",Clips!$B:$B,"<>site",Clips!$C:$C,"<>excluded") -> 0 | AF22: =COUNTIFS(Clips!$F:$F,$B22,Clips!$I:$I,"<5",Clips!$C:$C,"<>excluded") -> 0
A23: 170 | B23: Rufous-tailed Jacamar | C23: Galbula ruficauda | D23: rutjac1 | E23: bird | F23: core | G23: =IF(AND($E23="bird",$K23>0),"yes","") | I23: =IF($E23="bird",IF(COUNTIF('eBird List'!$A:$A,$B23)>0,"yes","no"),"") -> yes | J23: =IF(COUNTIF('eBird List'!$A:$A,$B23)=0,"",INDEX('eBird List'!$C:$C,MATCH($B23,'eBird List'!$A:$A,0))) -> 0.23680605 | K23: =COUNTIFS(Clips!$B:$B,"site",Clips!$F:$F,$B23)+COUNTIFS(Clips!$B:$B,"site",Clips!$O:$O,"*"&$B23&"*") -> 0 | L23: =COUNTIFS(Clips!$F:$F,$B23,Clips!$B:$B,"macaulay") -> 34 | M23: =COUNTIFS(Clips!$F:$F,$B23,Clips!$B:$B,"xeno-canto") -> 0 | N23: =K23+L23+M23 -> 34 | O23: =COUNTIFS(Clips!$F:$F,$B23,Clips!$C:$C,"excluded") -> 0 | P23: =COUNTIFS(Clips!$F:$F,$B23,Clips!$C:$C,"train") -> 24 | Q23: =COUNTIFS(Clips!$F:$F,$B23,Clips!$C:$C,"val") -> 5 | R23: =COUNTIFS(Clips!$F:$F,$B23,Clips!$C:$C,"test") -> 5 | S23: =SUMIFS(Clips!$I:$I,Clips!$F:$F,$B23,Clips!$C:$C,"train")/60 -> 11.774783 | T23: =SUMIFS(Clips!$I:$I,Clips!$F:$F,$B23,Clips!$C:$C,"val")/60 -> 2.6735333 | U23: =SUMIFS(Clips!$I:$I,Clips!$F:$F,$B23,Clips!$C:$C,"test")/60 -> 4.6638333 | V23: =SUMIFS(Clips!$J:$J,Clips!$F:$F,$B23,Clips!$C:$C,"train") -> 153 | W23: =IF(V23=0,"",Splits!$B$49/(Splits!$B$50*V23)) -> 1.0184671 | X23: =IF(P23>0,IF(AND(Q23>0,R23>0),"train + val + test",IF(R23>0,"train + test","train only")),IF(R23>0,"test only (unknown class)",IF(K23>0,"site extract only","no usable audio"))) -> train + val + test | Y23: =IF($P23=0,"",IF($E23="nonbird",$B23,IF($G23="yes",$B23,"other bird"))) -> other bird | Z23: =IF(AND($F23="core",$P23>0),$B23,"") -> Rufous-tailed Jacamar | AA23: =IF($P23>0,$B23,"") -> Rufous-tailed Jacamar | AB23: 32 | AC23: 22 | AD23: =IF(COUNTIFS(Clips!$F:$F,$B23,Clips!$M:$M,">0",Clips!$C:$C,"<>excluded")=0,"",AVERAGEIFS(Clips!$M:$M,Clips!$F:$F,$B23,Clips!$M:$M,">0",Clips!$C:$C,"<>excluded")) -> 3.7 | AE23: =COUNTIFS(Clips!$F:$F,$B23,Clips!$O:$O,"<>",Clips!$B:$B,"<>site",Clips!$C:$C,"<>excluded") -> 1 | AF23: =COUNTIFS(Clips!$F:$F,$B23,Clips!$I:$I,"<5",Clips!$C:$C,"<>excluded") -> 1
A24: 23 | B24: Black-faced Grosbeak | C24: Caryothraustes poliogaster | D24: blfgro1 | E24: bird | F24: core | G24: =IF(AND($E24="bird",$K24>0),"yes","") | I24: =IF($E24="bird",IF(COUNTIF('eBird List'!$A:$A,$B24)>0,"yes","no"),"") -> yes | J24: =IF(COUNTIF('eBird List'!$A:$A,$B24)=0,"",INDEX('eBird List'!$C:$C,MATCH($B24,'eBird List'!$A:$A,0))) -> 0.24952347 | K24: =COUNTIFS(Clips!$B:$B,"site",Clips!$F:$F,$B24)+COUNTIFS(Clips!$B:$B,"site",Clips!$O:$O,"*"&$B24&"*") -> 0 | L24: =COUNTIFS(Clips!$F:$F,$B24,Clips!$B:$B,"macaulay") -> 33 | M24: =COUNTIFS(Clips!$F:$F,$B24,Clips!$B:$B,"xeno-canto") -> 0 | N24: =K24+L24+M24 -> 33 | O24: =COUNTIFS(Clips!$F:$F,$B24,Clips!$C:$C,"excluded") -> 0 | P24: =COUNTIFS(Clips!$F:$F,$B24,Clips!$C:$C,"train") -> 23 | Q24: =COUNTIFS(Clips!$F:$F,$B24,Clips!$C:$C,"val") -> 5 | R24: =COUNTIFS(Clips!$F:$F,$B24,Clips!$C:$C,"test") -> 5 | S24: =SUMIFS(Clips!$I:$I,Clips!$F:$F,$B24,Clips!$C:$C,"train")/60 -> 26.5547 | T24: =SUMIFS(Clips!$I:$I,Clips!$F:$F,$B24,Clips!$C:$C,"val")/60 -> 6.0479 | U24: =SUMIFS(Clips!$I:$I,Clips!$F:$F,$B24,Clips!$C:$C,"test")/60 -> 9.6495833 | V24: =SUMIFS(Clips!$J:$J,Clips!$F:$F,$B24,Clips!$C:$C,"train") -> 333 | W24: =IF(V24=0,"",Splits!$B$49/(Splits!$B$50*V24)) -> 0.46794436 | X24: =IF(P24>0,IF(AND(Q24>0,R24>0),"train + val + test",IF(R24>0,"train + test","train only")),IF(R24>0,"test only (unknown class)",IF(K24>0,"site extract only","no usable audio"))) -> train + val + test | Y24: =IF($P24=0,"",IF($E24="nonbird",$B24,IF($G24="yes",$B24,"other bird"))) -> other bird | Z24: =IF(AND($F24="core",$P24>0),$B24,"") -> Black-faced Grosbeak | AA24: =IF($P24>0,$B24,"") -> Black-faced Grosbeak | AB24: 27 | AC24: 21 | AD24: =IF(COUNTIFS(Clips!$F:$F,$B24,Clips!$M:$M,">0",Clips!$C:$C,"<>excluded")=0,"",AVERAGEIFS(Clips!$M:$M,Clips!$F:$F,$B24,Clips!$M:$M,">0",Clips!$C:$C,"<>excluded")) -> 3.0428571 | AE24: =COUNTIFS(Clips!$F:$F,$B24,Clips!$O:$O,"<>",Clips!$B:$B,"<>site",Clips!$C:$C,"<>excluded") -> 5 | AF24: =COUNTIFS(Clips!$F:$F,$B24,Clips!$I:$I,"<5",Clips!$C:$C,"<>excluded") -> 1
A25: 159 | B25: Red-lored Amazon | C25: Amazona autumnalis | D25: relpar10 | E25: bird | F25: core | G25: =IF(AND($E25="bird",$K25>0),"yes","") -> yes | H25: yes | I25: =IF($E25="bird",IF(COUNTIF('eBird List'!$A:$A,$B25)>0,"yes","no"),"") -> yes | J25: =IF(COUNTIF('eBird List'!$A:$A,$B25)=0,"",INDEX('eBird List'!$C:$C,MATCH($B25,'eBird List'!$A:$A,0))) -> 0.32850846 | K25: =COUNTIFS(Clips!$B:$B,"site",Clips!$F:$F,$B25)+COUNTIFS(Clips!$B:$B,"site",Clips!$O:$O,"*"&$B25&"*") -> 2 | L25: =COUNTIFS(Clips!$F:$F,$B25,Clips!$B:$B,"macaulay") -> 32 | M25: =COUNTIFS(Clips!$F:$F,$B25,Clips!$B:$B,"xeno-canto") -> 1 | N25: =K25+L25+M25 -> 35 | O25: =COUNTIFS(Clips!$F:$F,$B25,Clips!$C:$C,"excluded") -> 0 | P25: =COUNTIFS(Clips!$F:$F,$B25,Clips!$C:$C,"train") -> 23 | Q25: =COUNTIFS(Clips!$F:$F,$B25,Clips!$C:$C,"val") -> 5 | R25: =COUNTIFS(Clips!$F:$F,$B25,Clips!$C:$C,"test") -> 5 | S25: =SUMIFS(Clips!$I:$I,Clips!$F:$F,$B25,Clips!$C:$C,"train")/60 -> 16.613417 | T25: =SUMIFS(Clips!$I:$I,Clips!$F:$F,$B25,Clips!$C:$C,"val")/60 -> 2.1013167 | U25: =SUMIFS(Clips!$I:$I,Clips!$F:$F,$B25,Clips!$C:$C,"test")/60 -> 4.7195167 | V25: =SUMIFS(Clips!$J:$J,Clips!$F:$F,$B25,Clips!$C:$C,"train") -> 212 | W25: =IF(V25=0,"",Splits!$B$49/(Splits!$B$50*V25)) -> 0.73502581 | X25: =IF(P25>0,IF(AND(Q25>0,R25>0),"train + val + test",IF(R25>0,"train + test","train only")),IF(R25>0,"test only (unknown class)",IF(K25>0,"site extract only","no usable audio"))) -> train + val + test | Y25: =IF($P25=0,"",IF($E25="nonbird",$B25,IF($G25="yes",$B25,"other bird"))) -> Red-lored Amazon | Z25: =IF(AND($F25="core",$P25>0),$B25,"") -> Red-lored Amazon | AA25: =IF($P25>0,$B25,"") -> Red-lored Amazon | AB25: 25 | AC25: 20 | AD25: =IF(COUNTIFS(Clips!$F:$F,$B25,Clips!$M:$M,">0",Clips!$C:$C,"<>excluded")=0,"",AVERAGEIFS(Clips!$M:$M,Clips!$F:$F,$B25,Clips!$M:$M,">0",Clips!$C:$C,"<>excluded")) -> 3.2180645 | AE25: =COUNTIFS(Clips!$F:$F,$B25,Clips!$O:$O,"<>",Clips!$B:$B,"<>site",Clips!$C:$C,"<>excluded") -> 6 | AF25: =COUNTIFS(Clips!$F:$F,$B25,Clips!$I:$I,"<5",Clips!$C:$C,"<>excluded") -> 0 | AG25: Site: Logged as Red lored parrot; both flagged Multiple birds? in the log
A26: 76 | B26: Dusky Antbird | C26: Cercomacroides tyrannina | D26: dusant1 | E26: bird | F26: core | G26: =IF(AND($E26="bird",$K26>0),"yes","") | I26: =IF($E26="bird",IF(COUNTIF('eBird List'!$A:$A,$B26)>0,"yes","no"),"") -> yes | J26: =IF(COUNTIF('eBird List'!$A:$A,$B26)=0,"",INDEX('eBird List'!$C:$C,MATCH($B26,'eBird List'!$A:$A,0))) -> 0.07496426 | K26: =COUNTIFS(Clips!$B:$B,"site",Clips!$F:$F,$B26)+COUNTIFS(Clips!$B:$B,"site",Clips!$O:$O,"*"&$B26&"*") -> 0 | L26: =COUNTIFS(Clips!$F:$F,$B26,Clips!$B:$B,"macaulay") -> 33 | M26: =COUNTIFS(Clips!$F:$F,$B26,Clips!$B:$B,"xeno-canto") -> 0 | N26: =K26+L26+M26 -> 33 | O26: =COUNTIFS(Clips!$F:$F,$B26,Clips!$C:$C,"excluded") -> 1 | P26: =COUNTIFS(Clips!$F:$F,$B26,Clips!$C:$C,"train") -> 22 | Q26: =COUNTIFS(Clips!$F:$F,$B26,Clips!$C:$C,"val") -> 5 | R26: =COUNTIFS(Clips!$F:$F,$B26,Clips!$C:$C,"test") -> 5 | S26: =SUMIFS(Clips!$I:$I,Clips!$F:$F,$B26,Clips!$C:$C,"train")/60 -> 18.165383 | T26: =SUMIFS(Clips!$I:$I,Clips!$F:$F,$B26,Clips!$C:$C,"val")/60 -> 4.1839833 | U26: =SUMIFS(Clips!$I:$I,Clips!$F:$F,$B26,Clips!$C:$C,"test")/60 -> 3.7661 | V26: =SUMIFS(Clips!$J:$J,Clips!$F:$F,$B26,Clips!$C:$C,"train") -> 228 | W26: =IF(V26=0,"",Splits!$B$49/(Splits!$B$50*V26)) -> 0.68344505 | X26: =IF(P26>0,IF(AND(Q26>0,R26>0),"train + val + test",IF(R26>0,"train + test","train only")),IF(R26>0,"test only (unknown class)",IF(K26>0,"site extract only","no usable audio"))) -> train + val + test | Y26: =IF($P26=0,"",IF($E26="nonbird",$B26,IF($G26="yes",$B26,"other bird"))) -> other bird | Z26: =IF(AND($F26="core",$P26>0),$B26,"") -> Dusky Antbird | AA26: =IF($P26>0,$B26,"") -> Dusky Antbird | AB26: 28 | AC26: 22 | AD26: =IF(COUNTIFS(Clips!$F:$F,$B26,Clips!$M:$M,">0",Clips!$C:$C,"<>excluded")=0,"",AVERAGEIFS(Clips!$M:$M,Clips!$F:$F,$B26,Clips!$M:$M,">0",Clips!$C:$C,"<>excluded")) -> 3.40625 | AE26: =COUNTIFS(Clips!$F:$F,$B26,Clips!$O:$O,"<>",Clips!$B:$B,"<>site",Clips!$C:$C,"<>excluded") -> 3 | AF26: =COUNTIFS(Clips!$F:$F,$B26,Clips!$I:$I,"<5",Clips!$C:$C,"<>excluded") -> 2
A27: 139 | B27: Ochre-bellied Flycatcher | C27: Mionectes oleagineus | D27: ocbfly1 | E27: bird | F27: core | G27: =IF(AND($E27="bird",$K27>0),"yes","") | I27: =IF($E27="bird",IF(COUNTIF('eBird List'!$A:$A,$B27)>0,"yes","no"),"") -> yes | J27: =IF(COUNTIF('eBird List'!$A:$A,$B27)=0,"",INDEX('eBird List'!$C:$C,MATCH($B27,'eBird List'!$A:$A,0))) -> 0.13268406 | K27: =COUNTIFS(Clips!$B:$B,"site",Clips!$F:$F,$B27)+COUNTIFS(Clips!$B:$B,"site",Clips!$O:$O,"*"&$B27&"*") -> 0 | L27: =COUNTIFS(Clips!$F:$F,$B27,Clips!$B:$B,"macaulay") -> 32 | M27: =COUNTIFS(Clips!$F:$F,$B27,Clips!$B:$B,"xeno-canto") -> 0 | N27: =K27+L27+M27 -> 32 | O27: =COUNTIFS(Clips!$F:$F,$B27,Clips!$C:$C,"excluded") -> 0 | P27: =COUNTIFS(Clips!$F:$F,$B27,Clips!$C:$C,"train") -> 22 | Q27: =COUNTIFS(Clips!$F:$F,$B27,Clips!$C:$C,"val") -> 5 | R27: =COUNTIFS(Clips!$F:$F,$B27,Clips!$C:$C,"test") -> 5 | S27: =SUMIFS(Clips!$I:$I,Clips!$F:$F,$B27,Clips!$C:$C,"train")/60 -> 31.489117 | T27: =SUMIFS(Clips!$I:$I,Clips!$F:$F,$B27,Clips!$C:$C,"val")/60 -> 10.3242 | U27: =SUMIFS(Clips!$I:$I,Clips!$F:$F,$B27,Clips!$C:$C,"test")/60 -> 4.7204667 | V27: =SUMIFS(Clips!$J:$J,Clips!$F:$F,$B27,Clips!$C:$C,"train") -> 389 | W27: =IF(V27=0,"",Splits!$B$49/(Splits!$B$50*V27)) -> 0.40057962 | X27: =IF(P27>0,IF(AND(Q27>0,R27>0),"train + val + test",IF(R27>0,"train + test","train only")),IF(R27>0,"test only (unknown class)",IF(K27>0,"site extract only","no usable audio"))) -> train + val + test | Y27: =IF($P27=0,"",IF($E27="nonbird",$B27,IF($G27="yes",$B27,"other bird"))) -> other bird | Z27: =IF(AND($F27="core",$P27>0),$B27,"") -> Ochre-bellied Flycatcher | AA27: =IF($P27>0,$B27,"") -> Ochre-bellied Flycatcher | AB27: 27 | AC27: 14 | AD27: =IF(COUNTIFS(Clips!$F:$F,$B27,Clips!$M:$M,">0",Clips!$C:$C,"<>excluded")=0,"",AVERAGEIFS(Clips!$M:$M,Clips!$F:$F,$B27,Clips!$M:$M,">0",Clips!$C:$C,"<>excluded")) -> 2.9603125 | AE27: =COUNTIFS(Clips!$F:$F,$B27,Clips!$O:$O,"<>",Clips!$B:$B,"<>site",Clips!$C:$C,"<>excluded") -> 1 | AF27: =COUNTIFS(Clips!$F:$F,$B27,Clips!$I:$I,"<5",Clips!$C:$C,"<>excluded") -> 0
